Workbook

Sheet RAT
B2: RAT - RELATÓRIO DE ATENDIMENTO
B3: EXECUÇÃO DOS SERVIÇOS
B4: Número da solicitação | D4: Data/hora Abertura | G4: Contrato de Manutenção | J4: Contratada
G5: 2024.7421.2057 | J5: MAFFENG ENGENHARIA E MANUTENÇÃO
B6: Sinistro | D6: Prazo de atendimento | G6: Tipo de Manutenção | J6: Nível de Ocorrência
B7: (Sim/Não) | G7: (Preventiva/Corretiva) | J7: (Emergencial/Urgente/Normal)
B8: Não | G8: Preventiva | J8: Normal
B9: Prefixo / SB - Dependência Beneficiada | G9: Endereço - Cidade
C10: =UPPER(VLOOKUP(B10,Prefixos!$A$1:$D$71,2,0)) -> #N/A | G10: =UPPER(VLOOKUP(B10,Prefixos!$A$1:$D$71,4,0)) -> #N/A
B11: Informações de Contato | G11: Matrícula / Nome - Funcionário Solicitante
B12: Responsável | G12: F2268209 - SISTEMA
B13: SERVIÇOS SOLICITADOS - Portal de Manutenção
B14: Descrição do serviço, Tipo, Quantidade, Local de Atendimento e Prioridade* | K14: Situação (Código**)
B15: Levantamento Preventivo | K15: 4
B16: * Preencher com as informações do Portal de Manutenção da DISEC. ** Preencher o campo situação com os códigos a seguir: 1. Serviço concluído sem pendências; 2. Serviço cancelado pelo demandante; 3. Atendimento Parcial; 4. Confecção de orçamento, para execução do serviço demanda autorização por parte do CESUP Suprimentos; 5. Não Atendido. 6. Mitigação de Riscos ou primeiro atendimento
B17: ORÇAMENTO DOS SERVIÇOS REALIZADOS
B18: ITEM | C18: DESCRIÇÃO | I18: QTD. | J18: UND. | K18: VALOR UNITÁRIO | M18: MAT UNIT | N18: MAO. UNIT | O18: MAT TOTAL | P18: MAO TOTAL | Q18: VALOR TOTAL
C19: =VLOOKUP(B19,'Valores Unitários'!$A$7:$J$516,2,0) -> #N/A | J19: =VLOOKUP(B19,'Valores Unitários'!$A$7:$J$516,4,0) -> #N/A | K19: =IFERROR(UPPER((VLOOKUP(B19,'Valores Unitários'!$A$7:$J$516,7,0))),"") | M19: =VLOOKUP(B19,'Valores Unitários'!$A$7:$J$516,5,0) -> #N/A | N19: =VLOOKUP(B19,'Valores Unitários'!$A$7:$J$516,6,0) -> #N/A | O19: =M19*I19 -> #N/A | P19: =N19*I19 -> #N/A | Q19: =K19*I19 -> #VALUE!
C20: =VLOOKUP(B20,'Valores Unitários'!$A$7:$J$516,2,0) -> #N/A | J20: =VLOOKUP(B20,'Valores Unitários'!$A$7:$J$516,4,0) -> #N/A | K20: =IFERROR(UPPER((VLOOKUP(B20,'Valores Unitários'!$A$7:$J$516,7,0))),"") | M20: =VLOOKUP(B20,'Valores Unitários'!$A$7:$J$516,5,0) -> #N/A | N20: =VLOOKUP(B20,'Valores Unitários'!$A$7:$J$516,6,0) -> #N/A | O20: =M20*I20 -> #N/A | P20: =N20*I20 -> #N/A | Q20: =K20*I20 -> #VALUE!
C21: =VLOOKUP(B21,'Valores Unitários'!$A$7:$J$516,2,0) -> #N/A | J21: =VLOOKUP(B21,'Valores Unitários'!$A$7:$J$516,4,0) -> #N/A | K21: =IFERROR(UPPER((VLOOKUP(B21,'Valores Unitários'!$A$7:$J$516,7,0))),"") | M21: =VLOOKUP(B21,'Valores Unitários'!$A$7:$J$516,5,0) -> #N/A | N21: =VLOOKUP(B21,'Valores Unitários'!$A$7:$J$516,6,0) -> #N/A | O21: =M21*I21 -> #N/A | P21: =N21*I21 -> #N/A | Q21: =K21*I21 -> #VALUE!
C22: =VLOOKUP(B22,'Valores Unitários'!$A$7:$J$516,2,0) -> #N/A | J22: =VLOOKUP(B22,'Valores Unitários'!$A$7:$J$516,4,0) -> #N/A | K22: =IFERROR(UPPER((VLOOKUP(B22,'Valores Unitários'!$A$7:$J$516,7,0))),"") | M22: =VLOOKUP(B22,'Valores Unitários'!$A$7:$J$516,5,0) -> #N/A | N22: =VLOOKUP(B22,'Valores Unitários'!$A$7:$J$516,6,0) -> #N/A | O22: =M22*I22 -> #N/A | P22: =N22*I22 -> #N/A | Q22: =K22*I22 -> #VALUE!
C23: =VLOOKUP(B23,'Valores Unitários'!$A$7:$J$516,2,0) -> #N/A | J23: =VLOOKUP(B23,'Valores Unitários'!$A$7:$J$516,4,0) -> #N/A | K23: =IFERROR(UPPER((VLOOKUP(B23,'Valores Unitários'!$A$7:$J$516,7,0))),"") | M23: =VLOOKUP(B23,'Valores Unitários'!$A$7:$J$516,5,0) -> #N/A | N23: =VLOOKUP(B23,'Valores Unitários'!$A$7:$J$516,6,0) -> #N/A | O23: =M23*I23 -> #N/A | P23: =N23*I23 -> #N/A | Q23: =K23*I23 -> #VALUE!
C24: =VLOOKUP(B24,'Valores Unitários'!$A$7:$J$516,2,0) -> #N/A | J24: =VLOOKUP(B24,'Valores Unitários'!$A$7:$J$516,4,0) -> #N/A | K24: =IFERROR(UPPER((VLOOKUP(B24,'Valores Unitários'!$A$7:$J$516,7,0))),"") | M24: =VLOOKUP(B24,'Valores Unitários'!$A$7:$J$516,5,0) -> #N/A | N24: =VLOOKUP(B24,'Valores Unitários'!$A$7:$J$516,6,0) -> #N/A | O24: =M24*I24 -> #N/A | P24: =N24*I24 -> #N/A | Q24: =K24*I24 -> #VALUE!
C25: =VLOOKUP(B25,'Valores Unitários'!$A$7:$J$516,2,0) -> #N/A | J25: =VLOOKUP(B25,'Valores Unitários'!$A$7:$J$516,4,0) -> #N/A | K25: =IFERROR(UPPER((VLOOKUP(B25,'Valores Unitários'!$A$7:$J$516,7,0))),"") | M25: =VLOOKUP(B25,'Valores Unitários'!$A$7:$J$516,5,0) -> #N/A | N25: =VLOOKUP(B25,'Valores Unitários'!$A$7:$J$516,6,0) -> #N/A | O25: =M25*I25 -> #N/A | P25: =N25*I25 -> #N/A | Q25: =K25*I25 -> #VALUE!
C26: =VLOOKUP(B26,'Valores Unitários'!$A$7:$J$516,2,0) -> #N/A | J26: =VLOOKUP(B26,'Valores Unitários'!$A$7:$J$516,4,0) -> #N/A | K26: =IFERROR(UPPER((VLOOKUP(B26,'Valores Unitários'!$A$7:$J$516,7,0))),"") | M26: =VLOOKUP(B26,'Valores Unitários'!$A$7:$J$516,5,0) -> #N/A | N26: =VLOOKUP(B26,'Valores Unitários'!$A$7:$J$516,6,0) -> #N/A | O26: =M26*I26 -> #N/A | P26: =N26*I26 -> #N/A | Q26: =K26*I26 -> #VALUE!
C27: =VLOOKUP(B27,'Valores Unitários'!$A$7:$J$516,2,0) -> #N/A | J27: =VLOOKUP(B27,'Valores Unitários'!$A$7:$J$516,4,0) -> #N/A | K27: =IFERROR(UPPER((VLOOKUP(B27,'Valores Unitários'!$A$7:$J$516,7,0))),"") | M27: =VLOOKUP(B27,'Valores Unitários'!$A$7:$J$516,5,0) -> #N/A | N27: =VLOOKUP(B27,'Valores Unitários'!$A$7:$J$516,6,0) -> #N/A | O27: =M27*I27 -> #N/A | P27: =N27*I27 -> #N/A | Q27: =K27*I27 -> #VALUE!
C28: =VLOOKUP(B28,'Valores Unitários'!$A$7:$J$516,2,0) -> #N/A | J28: =VLOOKUP(B28,'Valores Unitários'!$A$7:$J$516,4,0) -> #N/A | K28: =IFERROR(UPPER((VLOOKUP(B28,'Valores Unitários'!$A$7:$J$516,7,0))),"") | M28: =VLOOKUP(B28,'Valores Unitários'!$A$7:$J$516,5,0) -> #N/A | N28: =VLOOKUP(B28,'Valores Unitários'!$A$7:$J$516,6,0) -> #N/A | O28: =M28*I28 -> #N/A | P28: =N28*I28 -> #N/A | Q28: =K28*I28 -> #VALUE!
C29: =VLOOKUP(B29,'Valores Unitários'!$A$7:$J$516,2,0) -> #N/A | J29: =VLOOKUP(B29,'Valores Unitários'!$A$7:$J$516,4,0) -> #N/A | K29: =IFERROR(UPPER((VLOOKUP(B29,'Valores Unitários'!$A$7:$J$516,7,0))),"") | M29: =VLOOKUP(B29,'Valores Unitários'!$A$7:$J$516,5,0) -> #N/A | N29: =VLOOKUP(B29,'Valores Unitários'!$A$7:$J$516,6,0) -> #N/A | O29: =M29*I29 -> #N/A | P29: =N29*I29 -> #N/A | Q29: =K29*I29 -> #VALUE!
C30: =VLOOKUP(B30,'Valores Unitários'!$A$7:$J$516,2,0) -> #N/A | J30: =VLOOKUP(B30,'Valores Unitários'!$A$7:$J$516,4,0) -> #N/A | K30: =IFERROR(UPPER((VLOOKUP(B30,'Valores Unitários'!$A$7:$J$516,7,0))),"") | M30: =VLOOKUP(B30,'Valores Unitários'!$A$7:$J$516,5,0) -> #N/A | N30: =VLOOKUP(B30,'Valores Unitários'!$A$7:$J$516,6,0) -> #N/A | O30: =M30*I30 -> #N/A | P30: =N30*I30 -> #N/A | Q30: =K30*I30 -> #VALUE!
... C32: =VLOOKUP(B32,'Valores Unitários'!$A$7:$J$516,2,0) -> #N/A | J32: =VLOOKUP(B32,'Valores Unitários'!$A$7:$J$516,4,0) -> #N/A | K32: =IFERROR(UPPER((VLOOKUP(B32,'Valores Unitários'!$A$7:$J$516,7,0))),"") | M32: =VLOOKUP(B32,'Valores Unitários'!$A$7:$J$516,5,0) -> #N/A | N32: =VLOOKUP(B32,'Valores Unitários'!$A$7:$J$516,6,0) -> #N/A | O32: =M32*I32 -> #N/A | P32: =N32*I32 -> #N/A | Q32: =K32*I32 -> #VALUE!
B33: RESUMO DO ORÇAMENTO DOS SERVIÇOS SOLICITADOS
B34: Data / Hora Conclusão | G34: Valor de Materiais + Mão de Obra | J34: Valor Total
B35: =F49 -> 0 | G35: =SUM(O19:O32) -> #N/A | H35: + | I35: =SUM(P19:P32) -> #N/A | J35: =I35+G35 -> #N/A
B36: Observações
B41: ___________________________________________________ | H41: ___________________________________________________________________________________
B43: VISTO REPRESENTANTE DA EMPRESA CONTRATADA | H43: CARIMBO E VISTO DA DEPENDÊNCIA
B45: TÉCNICO | J45: ENGENHEIRO
J46: ______________________________________
B47: AUXILIAR
B49: Data e hora | E49: Data e hora | J49: RESPONSÁVEL TÉCNICO
...

Sheet Conformidade
B2: RAT - RELATÓRIO DE ATENDIMENTO
B3: Conformidade do atendimento no local dos serviços
B4: Número da solicitação | D4: Data/hora Abertura | G4: Contrato de Manutenção | J4: Contratada
B5: =RAT!B5 -> 0 | D5: =RAT!D5 -> 0 | G5: 2024.7421.2057 | J5: MAFFENG ENGENHARIA E MANUTENÇÃO
B6: Sinistro | D6: Prazo de atendimento | G6: Tipo de Manutenção | J6: Nível de Ocorrência
B7: (Sim/Não) | G7: (Preventiva/Corretiva) | J7: (Emergencial/Urgente/Normal)
B8: =RAT!B8 -> Não | D8: =RAT!D8 -> 0 | G8: =RAT!G8 -> Preventiva | J8: =RAT!J8 -> Normal
B9: Prefixo / SB - Dependência Beneficiada | G9: Endereço - Cidade
B10: =RAT!B10 -> 0 | C10: =RAT!C10 -> #N/A | G10: =RAT!G10 -> #N/A
B11: Informações de Contato | G11: Matrícula / Nome - Funcionário Solicitante
B12: =RAT!B12 -> Responsável | G12: =RAT!G12 -> F2268209 - SISTEMA
B13: MÓDULO DEMANDANTE / BENEFICIÁRIO / CONTRATANTE PREENCHIMENTO PELO PREPOSTO DO BANCO DO BRASIL
B14: Matrícula | D14: Nome Funcionário Preposto
B16: Questionário | J16: Atendeu | L16: Não Atendeu
B17: Prazo de Atendimento
B18: Qualidade dos serviços executados
B19: Discrição e Presteza dos funcionários
B20: RESUMO DO ORÇAMENTO DOS SERVIÇOS EXECUTADOS
B21: Data / Hora Conclusão | G21: Valor de Materiais + Mão de Obra | J21: Valor Total
B22: =RAT!F49 -> 0 | G22: =RAT!G35 -> #N/A | H22: + | I22: =RAT!I35 -> #N/A | J22: =RAT!J35 -> #N/A
B23: Observações
B25: Sr. ADMINISTRADOR PREDIAL, antes de assinar o RAT (Relatório de Atendimento), deve-se observar que:
B26: 1. A Situação (código, em "Serviços Solicitados") foi preenchida adequadamente para cada serviço solicitado e que os serviços
B27: registrados como concluídos, ficaram sem pendências;
B28: 2. Os serviços solicitados, porém não executados ou executados parcialmente, tiveram um valor descontado no campo "Resumo do Orçamento dos
B29: Serviços Executados".
B30: 3. O documento deverá ser totalmente preenchido, em todos os campos e sem rasuras. Inutilizar os espaços em branco;
B31: 4. A segunda via do RAT deverá ficar arquivada na dependência beneficiária para consultas futuras;
B32: 5. Deve-se registrar no Portal de Manutenção da DISEC as informações contidas no RAT.
B33: Dúvidas quanto aos itens, quantitativos e valores aplicados aos serviços, deverão ser sanadas com a CONTRATADA durante o atendimento. Caso não
B34: ocorra o esclarecimento, consultar o CESUP SUPRIMENTOS.
B35: Lembramos que o ADMINISTRADOR PREDIAL é o responsável pela fiscalização dos serviços executados na dependência e que a
... B37: dos serviços
C39: ________________________________________________ | I39: ___________________________________________________________________________________
C40: VISTO REPRESENTANTE DA EMPRESA CONTRATADA | I40: CARIMBO E VISTO DA DEPENDÊNCIA
B42: Parecer do Responsável Técnico / Contratada | J42: ENGENHEIRO
J48: CARIMBO - NÚMERO / VISTO DO CREA
B49: O RAT deverá ser emitido em 3 vias, sendo: a 1° Depêndencia Beneficiária, 2° Empresa Contratada, e em 3° CESUP Suprimentos

Sheet Valores Unitários
B1: A interessada deverá prrencher os campos em amarelo abaixo.
C3: CONSERVAÇÃO PREDIAL | M3: Informar nos campos em amarelo abaixo o desconto para MA e MO. Poderá ser informado desconto diferente ou igual para MA e MO de forma a ajustar o desconto global ao desconto ofertado na licitação. O campo em verde, após o preenchimento do MA, MO e BDI (em sua respectiva aba), deverá refletir o valor de desconto ofertado na Licitação. O valor efetivo de desconto de MA e MO considerando BDI aparecerá nos campos em Azul.
B4: PROPONENTE : | G4: LOTE: | H4: 04 | M4: Material sem BDI | N4: Mão de obra sem BDI
B5: MAFFENG ENGENHARIA E MANUTENCAO EIRELI | C5: CNPJ: | D5: 33.624.704/0001-94 | I5: DESCONTO: | J5: =N7 -> 0.31006343 | M5: 0.3601 | N5: 0.3601 | V5: Não mexer nos dados abaixo. Dados Sem BDI. | AB5: Não mexer nos dados abaixo. Dados com BDI. | AH5: Descontos Calculados
A7: ITEM | C7: QTDE | D7: UN. | E7: UNITÁRIO MATERIAL | F7: UNITÁRIO MÃO DE OBRA | G7: TOTAL UNITÁRIO DO ITEM | H7: TOTAL MATERIAL ROTEIRO | I7: TOTAL MÃO DE OBRA ROTEIRO | J7: TOTAL GERAL ROTEIRO | M7: Desconto Global Calculado com BDI | N7: =1-(J516/AF516) -> 0.31006343 | V7: QTDE | W7: UN. | X7: UNITÁRIO MATERIAL Referência | Y7: UNITÁRIO MÃO DE OBRA Referência | Z7: TOTAL UNITÁRIO DO ITEM Referência | AB7: QTDE | AC7: UN. | AD7: UNITÁRIO MATERIAL Referência | AE7: UNITÁRIO MÃO DE OBRA Referência | AF7: TOTAL UNITÁRIO DO ITEM Referência | AH7: UNITÁRIO MATERIAL Referência | AI7: UNITÁRIO MÃO DE OBRA Referência | AJ7: TOTAL UNITÁRIO DO ITEM Referência
A8: 1 | B8: PRELIMINARES | H8: =SUM(H9:H15) -> 534671.56 | I8: =SUM(I9:I15) -> 324422.94 | J8: =SUM(J9:J15) -> 859094.5 | M8: O valor do campo em verde deverá ser igual ao da proposta apresentada.
A9: 1.1 | B9: Chamado | C9: =V9 -> 1272 | D9: =W9 -> un | E9: 0 | F9: 92.13 | G9: =F9+E9 -> 92.13 | H9: =C9*E9 -> 0 | I9: =C9*F9 -> 117189.36 | J9: =SUM(E9:F9)*C9 -> 117189.36 | V9: 1272 | W9: un | X9: 0 | Y9: 91.79 | Z9: =SUM(X9:Y9) -> 91.79 | AB9: 1272 | AC9: un | AD9: 0 | AE9: 118.24 | AF9: =SUM(AD9:AE9) -> 118.24 | AH9: =IF(E9=0,0,(E9/AD9)-1) -> 0 | AI9: =IF(F9=0,0,(F9/AE9)-1) -> -0.22082206 | AJ9: =IF(G9=0,0,(G9/AF9)-1) -> -0.22082206
A10: 1.2 | B10: Deslocamento | C10: =V10 -> 159470 | D10: =W10 -> km | E10: 1.58 | F10: 0.83 | G10: =F10+E10 -> 2.41 | H10: =C10*E10 -> 251962.6 | I10: =C10*F10 -> 132360.1 | J10: =SUM(E10:F10)*C10 -> 384322.7 | V10: 159470 | W10: km | X10: 1.88 | Y10: 0.82 | Z10: =SUM(X10:Y10) -> 2.7 | AB10: 159470 | AC10: km | AD10: 2.42 | AE10: 1.06 | AF10: =SUM(AD10:AE10) -> 3.48 | AH10: =IF(E10=0,0,(E10/AD10)-1) -> -0.34710744 | AI10: =IF(F10=0,0,(F10/AE10)-1) -> -0.21698113 | AJ10: =IF(G10=0,0,(G10/AF10)-1) -> -0.30747126
A11: 1.3 | B11: Revisão de instalações | C11: =V11 -> 160 | D11: =W11 -> un | E11: 61.47 | F11: 364.58 | G11: =F11+E11 -> 426.05 | H11: =C11*E11 -> 9835.2 | I11: =C11*F11 -> 58332.8 | J11: =SUM(E11:F11)*C11 -> 68168 | V11: 160 | W11: un | X11: 88.78 | Y11: 377.3 | Z11: =SUM(X11:Y11) -> 466.08 | AB11: 160 | AC11: un | AD11: 114.37 | AE11: 486.04 | AF11: =SUM(AD11:AE11) -> 600.41 | AH11: =IF(E11=0,0,(E11/AD11)-1) -> -0.46253388 | AI11: =IF(F11=0,0,(F11/AE11)-1) -> -0.24989713 | AJ11: =IF(G11=0,0,(G11/AF11)-1) -> -0.29040156
A12: 1.4 | B12: Acompanhamento técnico em Segurança do Trabalho | C12: =V12 -> 69 | D12: =W12 -> un | E12: 0 | F12: 230.37 | G12: =F12+E12 -> 230.37 | H12: =C12*E12 -> 0 | I12: =C12*F12 -> 15895.53 | J12: =SUM(E12:F12)*C12 -> 15895.53 | V12: 69 | W12: un | X12: 0 | Y12: 274.56 | Z12: =SUM(X12:Y12) -> 274.56 | AB12: 69 | AC12: un | AD12: 0 | AE12: 353.69 | AF12: =SUM(AD12:AE12) -> 353.69 | AH12: =IF(E12=0,0,(E12/AD12)-1) -> 0 | AI12: =IF(F12=0,0,(F12/AE12)-1) -> -0.34866691 | AJ12: =IF(G12=0,0,(G12/AF12)-1) -> -0.34866691
A13: 1.5 | B13: Chamado Preventivo | C13: =V13 -> 160 | D13: =W13 -> un | E13: 1705.44 | F13: 0 | G13: =F13+E13 -> 1705.44 | H13: =C13*E13 -> 272870.4 | I13: =C13*F13 -> 0 | J13: =SUM(E13:F13)*C13 -> 272870.4 | V13: 160 | W13: un | X13: 2145.26 | Y13: 0 | Z13: =SUM(X13:Y13) -> 2145.26 | AB13: 160 | AC13: un | AD13: 2763.52 | AE13: 0 | AF13: =SUM(AD13:AE13) -> 2763.52 | AH13: =IF(E13=0,0,(E13/AD13)-1) -> -0.38287402 | AI13: =IF(F13=0,0,(F13/AE13)-1) -> 0 | AJ13: =IF(G13=0,0,(G13/AF13)-1) -> -0.38287402
A14: 1.6 | B14: Deslocamento Fluvial | C14: =V14 -> 1 | D14: =W14 -> Km | E14: 0.68 | F14: 1.65 | G14: =F14+E14 -> 2.33 | H14: =C14*E14 -> 0.68 | I14: =C14*F14 -> 1.65 | J14: =SUM(E14:F14)*C14 -> 2.33 | M14: Desconto Calculado Material Efetivo | N14: =IF(M5=0,0,ROUND(AH519,4)) -> -0.3492 | V14: 1 | W14: Km | X14: 0.78 | Y14: 1.67 | Z14: =SUM(X14:Y14) -> 2.45 | AB14: 1 | AC14: Km | AD14: 1 | AE14: 2.15 | AF14: =SUM(AD14:AE14) -> 3.15 | AH14: =IF(E14=0,0,(E14/AD14)-1) -> -0.32 | AI14: =IF(F14=0,0,(F14/AE14)-1) -> -0.23255814 | AJ14: =IF(G14=0,0,(G14/AF14)-1) -> -0.26031746
A15: 1.7 | B15: Laudo técncio fotográfico - Elementos de Sinalização - Padrão BB | C15: =V15 -> 1 | D15: =W15 -> UN | E15: 2.68 | F15: 643.5 | G15: =F15+E15 -> 646.18 | H15: =C15*E15 -> 2.68 | I15: =C15*F15 -> 643.5 | J15: =SUM(E15:F15)*C15 -> 646.18 | M15: Desconto Calculado Mão de Obra Efetivo | N15: =IF(N5=0,0,ROUND(AI519,4)) -> -0.263 | V15: 1 | W15: UN | X15: 92.28 | Y15: 646.9 | Z15: =SUM(X15:Y15) -> 739.18 | AB15: 1 | AC15: UN | AD15: 118.88 | AE15: 833.34 | AF15: =SUM(AD15:AE15) -> 952.22 | AH15: =IF(E15=0,0,(E15/AD15)-1) -> -0.97745626 | AI15: =IF(F15=0,0,(F15/AE15)-1) -> -0.22780618 | AJ15: =IF(G15=0,0,(G15/AF15)-1) -> -0.32139632
A16: 2 | B16: IMPLANTAÇÃO / ADMINISTRAÇÃO | E16: 0 | F16: 0 | H16: =SUM(H17:H52) -> 249041.51 | I16: =SUM(I17:I52) -> 345856.34 | J16: =SUM(J17:J52) -> 594897.85 | M16: Os valores acima consideram o valor informado na aba BDI. | AH16: =IF(E16=0,0,(E16/AD16)-1) -> 0 | AI16: =IF(F16=0,0,(F16/AE16)-1) -> 0 | AJ16: =IF(G16=0,0,(G16/AF16)-1) -> 0
A17: 2.1 | B17: Demolição manual de concreto simples | C17: =V17 -> 12 | D17: =W17 -> m³ | E17: 0 | F17: 252.25 | G17: =F17+E17 -> 252.25 | H17: =C17*E17 -> 0 | I17: =C17*F17 -> 3027 | J17: =SUM(E17:F17)*C17 -> 3027 | V17: 12 | W17: m³ | X17: 0 | Y17: 267.23 | Z17: =SUM(X17:Y17) -> 267.23 | AB17: 12 | AC17: m³ | AD17: 0 | AE17: 344.25 | AF17: =SUM(AD17:AE17) -> 344.25 | AH17: =IF(E17=0,0,(E17/AD17)-1) -> 0 | AI17: =IF(F17=0,0,(F17/AE17)-1) -> -0.26724764 | AJ17: =IF(G17=0,0,(G17/AF17)-1) -> -0.26724764
A18: 2.2 | B18: Demolição manual de alvenaria de elevação ou elemento vazado, incluindo revestimento | C18: =V18 -> 41 | D18: =W18 -> m³ | E18: 0 | F18: 58.21 | G18: =F18+E18 -> 58.21 | H18: =C18*E18 -> 0 | I18: =C18*F18 -> 2386.61 | J18: =SUM(E18:F18)*C18 -> 2386.61 | M18: A interessada pode alterar o BDI na respectiva aba da planilha eletrônica. A alteração do BDI afeta o desconto calculado efetivo de material e de mão de obra. O valor do BDI deverá ser igual ao da proposta a ser apresentada. | V18: 41 | W18: m³ | X18: 0 | Y18: 61.67 | Z18: =SUM(X18:Y18) -> 61.67 | AB18: 41 | AC18: m³ | AD18: 0 | AE18: 79.44 | AF18: =SUM(AD18:AE18) -> 79.44 | AH18: =IF(E18=0,0,(E18/AD18)-1) -> 0 | AI18: =IF(F18=0,0,(F18/AE18)-1) -> -0.26724572 | AJ18: =IF(G18=0,0,(G18/AF18)-1) -> -0.26724572
A19: 2.3 | B19: Demolição manual de revestimento em massa de parede ou teto ou Dry-Wall | C19: =V19 -> 204 | D19: =W19 -> m³ | E19: 0 | F19: 6.41 | G19: =F19+E19 -> 6.41 | H19: =C19*E19 -> 0 | I19: =C19*F19 -> 1307.64 | J19: =SUM(E19:F19)*C19 -> 1307.64 | V19: 204 | W19: m³ | X19: 0 | Y19: 6.89 | Z19: =SUM(X19:Y19) -> 6.89 | AB19: 204 | AC19: m³ | AD19: 0 | AE19: 8.88 | AF19: =SUM(AD19:AE19) -> 8.88 | AH19: =IF(E19=0,0,(E19/AD19)-1) -> 0 | AI19: =IF(F19=0,0,(F19/AE19)-1) -> -0.27815315 | AJ19: =IF(G19=0,0,(G19/AF19)-1) -> -0.27815315
A20: 2.4 | B20: Demolição de pisos em geral (ladrilho hidráulico, camada de enchimento, cerâmica, porcelanato, mármore, granito, pedra e madeira) - Manual | C20: =V20 -> 62 | D20: =W20 -> m² | E20: 0 | F20: 27.16 | G20: =F20+E20 -> 27.16 | H20: =C20*E20 -> 0 | I20: =C20*F20 -> 1683.92 | J20: =SUM(E20:F20)*C20 -> 1683.92 | V20: 62 | W20: m² | X20: 0 | Y20: 28.78 | Z20: =SUM(X20:Y20) -> 28.78 | AB20: 62 | AC20: m² | AD20: 0 | AE20: 37.07 | AF20: =SUM(AD20:AE20) -> 37.07 | AH20: =IF(E20=0,0,(E20/AD20)-1) -> 0 | AI20: =IF(F20=0,0,(F20/AE20)-1) -> -0.26733207 | AJ20: =IF(G20=0,0,(G20/AF20)-1) -> -0.26733207
A21: 2.5 | B21: Demolição de pisos em geral (ladrilho hidráulico, camada de enchimento, cerâmica, porcelanato, mármore, granito, pedra e madeira) - Mecanizado | C21: =V21 -> 128 | D21: =W21 -> m² | E21: 22.28 | F21: 13.58 | G21: =F21+E21 -> 35.86 | H21: =C21*E21 -> 2851.84 | I21: =C21*F21 -> 1738.24 | J21: =SUM(E21:F21)*C21 -> 4590.08 | V21: 128 | W21: m² | X21: 26.35 | Y21: 14.39 | Z21: =SUM(X21:Y21) -> 40.74 | AB21: 128 | AC21: m² | AD21: 33.94 | AE21: 18.54 | AF21: =SUM(AD21:AE21) -> 52.48 | AH21: =IF(E21=0,0,(E21/AD21)-1) -> -0.34354744 | AI21: =IF(F21=0,0,(F21/AE21)-1) -> -0.26752967 | AJ21: =IF(G21=0,0,(G21/AF21)-1) -> -0.31669207
A22: 2.6 | B22: Demolição de pavimentação com pré-moldado de concreto ou intertravado | C22: =V22 -> 1 | D22: =W22 -> m² | E22: 0 | F22: 13.58 | G22: =F22+E22 -> 13.58 | H22: =C22*E22 -> 0 | I22: =C22*F22 -> 13.58 | J22: =SUM(E22:F22)*C22 -> 13.58 | V22: 1 | W22: m² | X22: 0 | Y22: 14.39 | Z22: =SUM(X22:Y22) -> 14.39 | AB22: 1 | AC22: m² | AD22: 0 | AE22: 18.54 | AF22: =SUM(AD22:AE22) -> 18.54 | AH22: =IF(E22=0,0,(E22/AD22)-1) -> 0 | AI22: =IF(F22=0,0,(F22/AE22)-1) -> -0.26752967 | AJ22: =IF(G22=0,0,(G22/AF22)-1) -> -0.26752967
A23: 2.7 | B23: Demolição de piso cimentado sobre lastro de concreto | C23: =V23 -> 1 | D23: =W23 -> m² | E23: 0 | F23: 25.22 | G23: =F23+E23 -> 25.22 | H23: =C23*E23 -> 0 | I23: =C23*F23 -> 25.22 | J23: =SUM(E23:F23)*C23 -> 25.22 | V23: 1 | W23: m² | X23: 0 | Y23: 26.72 | Z23: =SUM(X23:Y23) -> 26.72 | AB23: 1 | AC23: m² | AD23: 0 | AE23: 34.42 | AF23: =SUM(AD23:AE23) -> 34.42 | AH23: =IF(E23=0,0,(E23/AD23)-1) -> 0 | AI23: =IF(F23=0,0,(F23/AE23)-1) -> -0.26728646 | AJ23: =IF(G23=0,0,(G23/AF23)-1) -> -0.26728646
A24: 2.8 | B24: Demolição manual de forro, inclusive sistema de fixação/tarugamento | C24: =V24 -> 1500 | D24: =W24 -> m² | E24: 0 | F24: 7.76 | G24: =F24+E24 -> 7.76 | H24: =C24*E24 -> 0 | I24: =C24*F24 -> 11640 | J24: =SUM(E24:F24)*C24 -> 11640 | M24: A interessada pode utilizar modelo próprio de planilha para cálculo,entretanto,a planilha final a ser apresentada juntamente com a proposta, deverá ter a mesma formatação do orçamento estimado que compõe a licitação. | V24: 1500 | W24: m² | X24: 0 | Y24: 8.22 | Z24: =SUM(X24:Y24) -> 8.22 | AB24: 1500 | AC24: m² | AD24: 0 | AE24: 10.59 | AF24: =SUM(AD24:AE24) -> 10.59 | AH24: =IF(E24=0,0,(E24/AD24)-1) -> 0 | AI24: =IF(F24=0,0,(F24/AE24)-1) -> -0.26723324 | AJ24: =IF(G24=0,0,(G24/AF24)-1) -> -0.26723324
A25: 2.9 | B25: Demolição de contrapiso/argamassa regularizante, isolante ou protetora | C25: =V25 -> 9 | D25: =W25 -> m² | E25: 0 | F25: 9.7 | G25: =F25+E25 -> 9.7 | H25: =C25*E25 -> 0 | I25: =C25*F25 -> 87.3 | J25: =SUM(E25:F25)*C25 -> 87.3 | V25: 9 | W25: m² | X25: 0 | Y25: 10.28 | Z25: =SUM(X25:Y25) -> 10.28 | AB25: 9 | AC25: m² | AD25: 0 | AE25: 13.24 | AF25: =SUM(AD25:AE25) -> 13.24 | AH25: =IF(E25=0,0,(E25/AD25)-1) -> 0 | AI25: =IF(F25=0,0,(F25/AE25)-1) -> -0.2673716 | AJ25: =IF(G25=0,0,(G25/AF25)-1) -> -0.2673716
A26: 2.10 | B26: Demolição de estrutura em madeira para telhado | C26: =V26 -> 1 | D26: =W26 -> m² | E26: 0 | F26: 27.27 | G26: =F26+E26 -> 27.27 | H26: =C26*E26 -> 0 | I26: =C26*F26 -> 27.27 | J26: =SUM(E26:F26)*C26 -> 27.27 | V26: 1 | W26: m² | X26: 0 | Y26: 28.94 | Z26: =SUM(X26:Y26) -> 28.94 | AB26: 1 | AC26: m² | AD26: 0 | AE26: 37.28 | AF26: =SUM(AD26:AE26) -> 37.28 | AH26: =IF(E26=0,0,(E26/AD26)-1) -> 0 | AI26: =IF(F26=0,0,(F26/AE26)-1) -> -0.26850858 | AJ26: =IF(G26=0,0,(G26/AF26)-1) -> -0.26850858
A27: 2.11 | B27: Retirada de cumeeira, espigão, rufo, calha ou chapim, perfil qualquer | C27: =V27 -> 357 | D27: =W27 -> m | E27: 0 | F27: 13.47 | G27: =F27+E27 -> 13.47 | H27: =C27*E27 -> 0 | I27: =C27*F27 -> 4808.79 | J27: =SUM(E27:F27)*C27 -> 4808.79 | V27: 357 | W27: m | X27: 0 | Y27: 14.21 | Z27: =SUM(X27:Y27) -> 14.21 | AB27: 357 | AC27: m | AD27: 0 | AE27: 18.31 | AF27: =SUM(AD27:AE27) -> 18.31 | AH27: =IF(E27=0,0,(E27/AD27)-1) -> 0 | AI27: =IF(F27=0,0,(F27/AE27)-1) -> -0.26433643 | AJ27: =IF(G27=0,0,(G27/AF27)-1) -> -0.26433643
A28: 2.12 | B28: Retirada de piso tátil com limpeza | C28: =V28 -> 6000 | D28: =W28 -> m² | E28: 14.97 | F28: 21.9 | G28: =F28+E28 -> 36.87 | H28: =C28*E28 -> 89820 | I28: =C28*F28 -> 131400 | J28: =SUM(E28:F28)*C28 -> 221220 | V28: 6000 | W28: m² | X28: 17.69 | Y28: 23.05 | Z28: =SUM(X28:Y28) -> 40.74 | AB28: 6000 | AC28: m² | AD28: 22.79 | AE28: 29.69 | AF28: =SUM(AD28:AE28) -> 52.48 | AH28: =IF(E28=0,0,(E28/AD28)-1) -> -0.34313295 | AI28: =IF(F28=0,0,(F28/AE28)-1) -> -0.26237791 | AJ28: =IF(G28=0,0,(G28/AF28)-1) -> -0.29744665
A29: 2.13 | B29: Remoção de revestimento de piso de carpete ou manta vinílica | C29: =V29 -> 3375 | D29: =W29 -> m² | E29: 14.97 | F29: 11.27 | G29: =F29+E29 -> 26.24 | H29: =C29*E29 -> 50523.75 | I29: =C29*F29 -> 38036.25 | J29: =SUM(E29:F29)*C29 -> 88560 | V29: 3375 | W29: m² | X29: 17.69 | Y29: 11.84 | Z29: =SUM(X29:Y29) -> 29.53 | AB29: 3375 | AC29: m² | AD29: 22.79 | AE29: 15.25 | AF29: =SUM(AD29:AE29) -> 38.04 | AH29: =IF(E29=0,0,(E29/AD29)-1) -> -0.34313295 | AI29: =IF(F29=0,0,(F29/AE29)-1) -> -0.26098361 | AJ29: =IF(G29=0,0,(G29/AF29)-1) -> -0.31019979
A30: 2.14 | B30: Ajuste de Piso Elevado (remoção e recolocação de revestimentos e placas do piso inclusive) | C30: =V30 -> 661 | D30: =W30 -> m² | E30: 8.58 | F30: 58.16 | G30: =F30+E30 -> 66.74 | H30: =C30*E30 -> 5671.38 | I30: =C30*F30 -> 38443.76 | J30: =SUM(E30:F30)*C30 -> 44115.14 | V30: 661 | W30: m² | X30: 9.34 | Y30: 61.12 | Z30: =SUM(X30:Y30) -> 70.46 | AB30: 661 | AC30: m² | AD30: 12.03 | AE30: 78.73 | AF30: =SUM(AD30:AE30) -> 90.76 | AH30: =IF(E30=0,0,(E30/AD30)-1) -> -0.28678304 | AI30: =IF(F30=0,0,(F30/AE30)-1) -> -0.2612727 | AJ30: =IF(G30=0,0,(G30/AF30)-1) -> -0.26465403
A31: 2.15 | B31: Retirada de piso elevado, inclusive estrutura de sustentação | C31: =V31 -> 724 | D31: =W31 -> m² | E31: 0 | F31: 25.18 | G31: =F31+E31 -> 25.18 | H31: =C31*E31 -> 0 | I31: =C31*F31 -> 18230.32 | J31: =SUM(E31:F31)*C31 -> 18230.32 | V31: 724 | W31: m² | X31: 0 | Y31: 26.71 | Z31: =SUM(X31:Y31) -> 26.71 | AB31: 724 | AC31: m² | AD31: 0 | AE31: 34.41 | AF31: =SUM(AD31:AE31) -> 34.41 | AH31: =IF(E31=0,0,(E31/AD31)-1) -> 0 | AI31: =IF(F31=0,0,(F31/AE31)-1) -> -0.26823598 | AJ31: =IF(G31=0,0,(G31/AF31)-1) -> -0.26823598
A32: 2.16 | B32: Reinstalação de piso elevado proveniente de reaproveitamento, incluso material | C32: =V32 -> 1 | D32: =W32 -> m² | E32: 1.43 | F32: 62.97 | G32: =F32+E32 -> 64.4 | H32: =C32*E32 -> 1.43 | I32: =C32*F32 -> 62.97 | J32: =SUM(E32:F32)*C32 -> 64.4 | V32: 1 | W32: m² | X32: 1.62 | Y32: 66.17 | Z32: =SUM(X32:Y32) -> 67.79 | AB32: 1 | AC32: m² | AD32: 2.09 | AE32: 85.24 | AF32: =SUM(AD32:AE32) -> 87.33 | AH32: =IF(E32=0,0,(E32/AD32)-1) -> -0.31578947 | AI32: =IF(F32=0,0,(F32/AE32)-1) -> -0.26126232 | AJ32: =IF(G32=0,0,(G32/AF32)-1) -> -0.26256727
A33: 2.17 | B33: Retirada ou recolocação de vidro | C33: =V33 -> 415 | D33: =W33 -> m² | E33: 13.29 | F33: 14.36 | G33: =F33+E33 -> 27.65 | H33: =C33*E33 -> 5515.35 | I33: =C33*F33 -> 5959.4 | J33: =SUM(E33:F33)*C33 -> 11474.75 | V33: 415 | W33: m² | X33: 12.9 | Y33: 15.15 | Z33: =SUM(X33:Y33) -> 28.05 | AB33: 415 | AC33: m² | AD33: 16.62 | AE33: 19.52 | AF33: =SUM(AD33:AE33) -> 36.14 | AH33: =IF(E33=0,0,(E33/AD33)-1) -> -0.20036101 | AI33: =IF(F33=0,0,(F33/AE33)-1) -> -0.26434426 | AJ33: =IF(G33=0,0,(G33/AF33)-1) -> -0.23491976
A34: 2.18 | B34: Remoção de entulho com caçamba metálica, inclusive limpeza, transporte, carga, descarga e descarte conforme legislação ambiental - Material de descarte (alvenaria, estruturas metálicas, madeiramento, revestimentos cerâmicos, gesso, dry-wall, entre outros) | C34: =V34 -> 30 | D34: =W34 -> m³ | E34: 48.55 | F34: 11.94 | G34: =F34+E34 -> 60.49 | H34: =C34*E34 -> 1456.5 | I34: =C34*F34 -> 358.2 | J34: =SUM(E34:F34)*C34 -> 1814.7 | V34: 30 | W34: m³ | X34: 61.2 | Y34: 12.68 | Z34: =SUM(X34:Y34) -> 73.88 | AB34: 30 | AC34: m³ | AD34: 78.84 | AE34: 16.33 | AF34: =SUM(AD34:AE34) -> 95.17 | AH34: =IF(E34=0,0,(E34/AD34)-1) -> -0.38419584 | AI34: =IF(F34=0,0,(F34/AE34)-1) -> -0.26883037 | AJ34: =IF(G34=0,0,(G34/AF34)-1) -> -0.36440055
A35: 2.19 | B35: Remoção / Remanejamento de placa aérea | C35: =V35 -> 126 | D35: =W35 -> un | E35: 5.61 | F35: 37.73 | G35: =F35+E35 -> 43.34 | H35: =C35*E35 -> 706.86 | I35: =C35*F35 -> 4753.98 | J35: =SUM(E35:F35)*C35 -> 5460.84 | V35: 126 | W35: un | X35: 5.84 | Y35: 40 | Z35: =SUM(X35:Y35) -> 45.84 | AB35: 126 | AC35: un | AD35: 7.52 | AE35: 51.53 | AF35: =SUM(AD35:AE35) -> 59.05 | AH35: =IF(E35=0,0,(E35/AD35)-1) -> -0.25398936 | AI35: =IF(F35=0,0,(F35/AE35)-1) -> -0.26780516 | AJ35: =IF(G35=0,0,(G35/AF35)-1) -> -0.26604572
A36: 2.20 | B36: Andaime tubular fachadeiro | C36: =V36 -> 1822 | D36: =W36 -> m²/mês | E36: 12.6 | F36: 6.82 | G36: =F36+E36 -> 19.42 | H36: =C36*E36 -> 22957.2 | I36: =C36*F36 -> 12426.04 | J36: =SUM(E36:F36)*C36 -> 35383.24 | V36: 1822 | W36: m²/mês | X36: 15.45 | Y36: 7.43 | Z36: =SUM(X36:Y36) -> 22.88 | AB36: 1822 | AC36: m²/mês | AD36: 19.9 | AE36: 9.57 | AF36: =SUM(AD36:AE36) -> 29.47 | AH36: =IF(E36=0,0,(E36/AD36)-1) -> -0.36683417 | AI36: =IF(F36=0,0,(F36/AE36)-1) -> -0.28735632 | AJ36: =IF(G36=0,0,(G36/AF36)-1) -> -0.34102477
... A52: 2.36 | B52: Tela para Andaime | C52: =V52 -> 1 | D52: =W52 -> m² | E52: 2.51 | F52: 2.99 | G52: =F52+E52 -> 5.5 | H52: =C52*E52 -> 2.51 | I52: =C52*F52 -> 2.99 | J52: =SUM(E52:F52)*C52 -> 5.5 | V52: 1 | W52: m² | X52: 3.63 | Y52: 3.15 | Z52: =SUM(X52:Y52) -> 6.78 | AB52: 1 | AC52: m² | AD52: 4.68 | AE52: 4.06 | AF52: =SUM(AD52:AE52) -> 8.74 | AH52: =IF(E52=0,0,(E52/AD52)-1) -> -0.46367521 | AI52: =IF(F52=0,0,(F52/AE52)-1) -> -0.2635468 | AJ52: =IF(G52=0,0,(G52/AF52)-1) -> -0.37070938
A53: 3 | B53: MOVIMENTO DE TERRA | E53: 0 | F53: 0 | H53: 0 | I53: 0 | J53: 0 | AH53: =IF(E53=0,0,(E53/AD53)-1) -> 0 | AI53: =IF(F53=0,0,(F53/AE53)-1) -> 0 | AJ53: =IF(G53=0,0,(G53/AF53)-1) -> 0
A54: 4 | B54: FUNDAÇÃO | E54: 0 | F54: 0 | H54: 0 | I54: 0 | J54: 0 | AH54: =IF(E54=0,0,(E54/AD54)-1) -> 0 | AI54: =IF(F54=0,0,(F54/AE54)-1) -> 0 | AJ54: =IF(G54=0,0,(G54/AF54)-1) -> 0
A55: 5 | B55: ESTRUTURA | E55: 0 | F55: 0 | H55: =SUM(H56:H59) -> 1650.25 | I55: =SUM(I56:I59) -> 450.1 | J55: =SUM(J56:J59) -> 2100.35 | AH55: =IF(E55=0,0,(E55/AD55)-1) -> 0 | AI55: =IF(F55=0,0,(F55/AE55)-1) -> 0 | AJ55: =IF(G55=0,0,(G55/AF55)-1) -> 0
A56: 5.1 | B56: Base de concreto para fixação de TAA/TTE | C56: =V56 -> 1 | D56: =W56 -> m³ | E56: 729.79 | F56: 48.52 | G56: =F56+E56 -> 778.31 | H56: =C56*E56 -> 729.79 | I56: =C56*F56 -> 48.52 | J56: =SUM(E56:F56)*C56 -> 778.31 | V56: 1 | W56: m³ | X56: 933.69 | Y56: 51.34 | Z56: =SUM(X56:Y56) -> 985.03 | AB56: 1 | AC56: m³ | AD56: 1202.78 | AE56: 66.14 | AF56: =SUM(AD56:AE56) -> 1268.92 | AH56: =IF(E56=0,0,(E56/AD56)-1) -> -0.39324731 | AI56: =IF(F56=0,0,(F56/AE56)-1) -> -0.2664046 | AJ56: =IF(G56=0,0,(G56/AF56)-1) -> -0.38663588
A57: 5.2 | B57: Montagem e Desmontagem de escoramento em madeira. | C57: =V57 -> 1 | D57: =W57 -> m² | E57: 141.62 | F57: 54.03 | G57: =F57+E57 -> 195.65 | H57: =C57*E57 -> 141.62 | I57: =C57*F57 -> 54.03 | J57: =SUM(E57:F57)*C57 -> 195.65 | V57: 1 | W57: m² | X57: 179.43 | Y57: 56.59 | Z57: =SUM(X57:Y57) -> 236.02 | AB57: 1 | AC57: m² | AD57: 231.14 | AE57: 72.9 | AF57: =SUM(AD57:AE57) -> 304.04 | AH57: =IF(E57=0,0,(E57/AD57)-1) -> -0.38729774 | AI57: =IF(F57=0,0,(F57/AE57)-1) -> -0.25884774 | AJ57: =IF(G57=0,0,(G57/AF57)-1) -> -0.35649914
...

Sheet Prefixos
A1: Relação das Dependências do Rot - Varginha
A4: PREFIXO | B4: DEPENDÊNCIAS | C4: DISTÂNCIA EM RELAÇÃO A CIDADE BASE - IDA E VOLTA (KM) | D4: CIDADE
A5: 8672 | B5: EMPRESA POUSO ALEGRE | C5: 252 | D5: POUSO ALEGRE
A6: 8675 | B6: EMPRESA POCOS CALDAS | C6: 308 | D6: POCOS DE CALDAS
A7: 12 | B7: TRES CORACOES | C7: 69 | D7: TRES CORACOES
A8: 32 | B8: VARGINHA | C8: 10 | D8: VARGINHA
A9: 64 | B9: GUAXUPE | C9: 328 | D9: GUAXUPE
A10: 168 | B10: ALFENAS | C10: 139 | D10: ALFENAS
A11: 168 | B11: UNIFAL | C11: 139 | D11: ALFENAS
A12: 205 | B12: OURO FINO | C12: 358 | D12: OURO FINO
A13: 308 | B13: FORUM WENCESLAU BRAZ | C13: 366 | D13: ITAJUBA
A14: 308 | B14: EFEI - ESC.FED.ENGEN | C14: 366 | D14: ITAJUBA
A15: 308 | B15: ITAJUBA | C15: 366 | D15: ITAJUBA
A16: 309 | B16: FORUM POCOS DE CALDA | C16: 308 | D16: POCOS DE CALDAS
... A71: 8220 | B71: BOM REPOUSO | C71: 348 | D71: BOM REPOUSO

Sheet BDI
B1: O interessado deverá preencher os campos em amarelo de forma a obter o valor do BDI. | E1: O BDI pode ser alterado pela interessada. A alteração do BDI afeta o valor final da proposta. O valor do BDI deverá ser igual ao da proposta a ser apresentada.
B3: COMPOSIÇÃO ESTIMADA DO BDI (DESONERADO)
B6: ÍNDICES BDI - Serviços, subcontratações e acionamentos de Serviços de Engenharia.
B9: CUSTOS INDIRETOS
B10: Administração Central (AC) | C10: 0.03
B11: Seguros (S) + Garantia (G) | C11: 0.008
B12: Riscos R) | C12: 0.0097
B13: Despesas Financeiras (DF) | C13: 0.0059
B14: BONIFICAÇÃO
B15: Lucro Bruto (LB) | C15: 0.0616
B16: TRIBUTOS (T)
B17: ISS | C17: 0.05
B18: PIS / PASEP | C18: 0.0065
B19: COFINS | C19: 0.03
B20: CPRB | C20: 0.045
B21: BDI SERVIÇOS | C21: =ROUND(((1+(C10+C11+C12))*(1+C13)*(1+C15))/(1-(C17+C18+C19+C20))-1,4) -> 0.2882
B22: BDI = [[(1+(AC+S+G+R))*(1+DF)*(1+LB)]/(1-T)]-1
B26: 1 - O cálculo do BDI segue a metodologia estabelecida no item 9.10 do Voto do Acórdão 2369/2011 - TCU - Plenário. O IR e a CSLL não fazem parte do cálculo. 2 - Valores Referenciais dados pelo Acórdão 2622/2013 - TCU - Plenário. 3 - A parcela referente aos Seguros (S) é inversa à parcela de Riscos (R), ou seja, quanto maior a cobertura dos seguros contratados, menor a taxa de risco a ser considerada no BDI. Sendo assim, optou-se por representá-las na planilha de forma unificada. Poderão estar contabilizados na parcela os Seguros de Risco de Engenharia e de Responsabilidade Civil, dentre outros. 4 - Conforme orientações do TCU, publicadas no guia ORIENTAÇÕES PARA ELABORAÇÃO DE PLANILHAS ORÇAMENTÁRIAS DE OBRAS PÚBLICAS, a CPRB (Contribuição Previdenciária Sobre a Receita Bruta) deve ser incluída no cálculo do BDI de orçamentos que consideram a desoneração da folha de pagamentos.
B28: Observação: O PROPONENTE utilizará a incidência da CPRB somente se estiver enquadrado como desonerado.
