Workbook

Sheet Planilha1
A1: Itens
B2: =VLOOKUP(A2,Valores!$A$1:$D$529,2,0) -> #N/A | C2: 1 | D2: =VLOOKUP(A2,Valores!$A$1:$D$529,4,0) -> #N/A
A3: 16.16 | B3: =VLOOKUP(A3,Valores!$A$1:$D$529,2,0) -> Persiana vertical em tecido | C3: 1.4 | D3: =VLOOKUP(A3,Valores!$A$1:$D$529,4,0) -> m²
A4: 2.18 | B4: =VLOOKUP(A4,Valores!$A$1:$D$529,2,0) -> Remoção de entulho com caçamba metálica, inclusive limpeza, transporte, carga, descarga e descarte conforme legislação ambiental - Material de descarte (alvenaria, estruturas metálicas, madeiramento, revestimentos cerâmicos, gesso, dry-wall, entre outros) | C4: 0.14 | D4: =VLOOKUP(A4,Valores!$A$1:$D$529,4,0) -> m³
B5: =VLOOKUP(A5,Valores!$A$1:$D$529,2,0) -> #N/A | D5: =VLOOKUP(A5,Valores!$A$1:$D$529,4,0) -> #N/A
B6: =VLOOKUP(A6,Valores!$A$1:$D$529,2,0) -> #N/A | D6: =VLOOKUP(A6,Valores!$A$1:$D$529,4,0) -> #N/A
B7: =VLOOKUP(A7,Valores!$A$1:$D$529,2,0) -> #N/A | D7: =VLOOKUP(A7,Valores!$A$1:$D$529,4,0) -> #N/A
B8: =VLOOKUP(A8,Valores!$A$1:$D$529,2,0) -> #N/A | D8: =VLOOKUP(A8,Valores!$A$1:$D$529,4,0) -> #N/A
B9: =VLOOKUP(A9,Valores!$A$1:$D$529,2,0) -> #N/A | C9: 1 | D9: =VLOOKUP(A9,Valores!$A$1:$D$529,4,0) -> #N/A
A10: 29.22 | B10: =VLOOKUP(A10,Valores!$A$1:$D$529,2,0) -> Ajuste de biombo, divisórias, carenagens e mobiliário em geral | C10: 6 | D10: =VLOOKUP(A10,Valores!$A$1:$D$529,4,0) -> un
A11: 10.5 | B11: =VLOOKUP(A11,Valores!$A$1:$D$529,2,0) -> Peitoril ou soleira de granito, assentado e rejuntado | D11: =VLOOKUP(A11,Valores!$A$1:$D$529,4,0) -> m
B12: =VLOOKUP(A12,Valores!$A$1:$D$529,2,0) -> #N/A | D12: =VLOOKUP(A12,Valores!$A$1:$D$529,4,0) -> #N/A
B13: =VLOOKUP(A13,Valores!$A$1:$D$529,2,0) -> #N/A | D13: =VLOOKUP(A13,Valores!$A$1:$D$529,4,0) -> #N/A
B14: =VLOOKUP(A14,Valores!$A$1:$D$529,2,0) -> #N/A | D14: =VLOOKUP(A14,Valores!$A$1:$D$529,4,0) -> #N/A
B15: =VLOOKUP(A15,Valores!$A$1:$D$529,2,0) -> #N/A | D15: =VLOOKUP(A15,Valores!$A$1:$D$529,4,0) -> #N/A
D16: .

Sheet Valores
A1: ITEM | C1: QTDE | D1: UN.
A2: 1 | B2: PRELIMINARES
A3: 1.1 | B3: Chamado | C3: =V3 -> 0 | D3: un
A4: 1.2 | B4: Deslocamento | C4: =V4 -> 0 | D4: km
A5: 1.3 | B5: Revisão de instalações | C5: =V5 -> 0 | D5: un
A6: 1.4 | B6: Acompanhamento técnico em Segurança do Trabalho | C6: =V6 -> 0 | D6: un
A7: 1.5 | B7: Hospedagem de equipe técnica - Serviços prolongados | C7: =V7 -> 0 | D7: un
A8: 1.6 | B8: Deslocamento Fluvial | C8: =V8 -> 0 | D8: Km
A9: 1.7 | B9: Laudo técnico fotográfico - Elementos de Sinalização - Padrão BB | C9: =V9 -> 0 | D9: UN
A10: 2 | B10: IMPLANTAÇÃO / ADMINISTRAÇÃO
A11: 2.1 | B11: Demolição manual de concreto simples | C11: =V11 -> 0 | D11: m³
A12: 2.2 | B12: Demolição manual de alvenaria de elevação ou elemento vazado, incluindo revestimento | C12: =V12 -> 0 | D12: m³
A13: 2.3 | B13: Demolição manual de revestimento em massa de parede ou teto ou Dry-Wall | C13: =V13 -> 0 | D13: m³
A14: 2.4 | B14: Demolição de pisos em geral (ladrilho hidráulico, camada de enchimento, cerâmica, porcelanato, mármore, granito, pedra e madeira) - Manual | C14: =V14 -> 0 | D14: m²
A15: 2.5 | B15: Demolição de pisos em geral (ladrilho hidráulico, camada de enchimento, cerâmica, porcelanato, mármore, granito, pedra e madeira) - Mecanizado | C15: =V15 -> 0 | D15: m²
A16: 2.6 | B16: Demolição de pavimentação com pré-moldado de concreto ou intertravado | C16: =V16 -> 0 | D16: m²
A17: 2.7 | B17: Demolição de piso cimentado sobre lastro de concreto | C17: =V17 -> 0 | D17: m²
A18: 2.8 | B18: Demolição manual de forro, inclusive sistema de fixação/tarugamento | C18: =V18 -> 0 | D18: m²
A19: 2.9 | B19: Demolição de contrapiso/argamassa regularizante, isolante ou protetora | C19: =V19 -> 0 | D19: m²
A20: 2.10 | B20: Demolição de estrutura em madeira para telhado | C20: =V20 -> 0 | D20: m²
A21: 2.11 | B21: Retirada de cumeeira, espigão, rufo, calha ou chapim, perfil qualquer | C21: =V21 -> 0 | D21: m
A22: 2.12 | B22: Retirada de piso tátil com limpeza | C22: =V22 -> 0 | D22: m²
... A46: 2.36 | B46: Tela para Andaime | C46: =V46 -> 0 | D46: m²
A47: 3 | B47: MOVIMENTO DE TERRA
A48: 3.1 | B48: Escavação Manual em Solo | C48: =V48 -> 0 | D48: m³
A49: 3.2 | B49: Reaterro/Aterro Manual de Solo | C49: =V49 -> 0 | D49: m³
A50: 4 | B50: FUNDAÇÃO
A51: 5 | B51: ESTRUTURA
A52: 5.1 | B52: Base de concreto para fixação de TAA/TTE | C52: =V52 -> 0 | D52: m³
A53: 5.2 | B53: Montagem e Desmontagem de escoramento em madeira. | C53: =V53 -> 0 | D53: m²
A54: 5.3 | B54: Montagem e Desmontagem de escoramento metálico. | C54: =V54 -> 0 | D54: m²
A55: 5.4 | B55: Concreto fck = 15 MPa, controle tipo "B", e = 10 cm, e armado com tela de aço CA-60 | C55: =V55 -> 0 | D55: m²
A56: 6 | B56: ALVENARIAS E OUTRAS VEDAÇÕES
A57: 6.1 | B57: Alvenaria com tijolo cerâmico furado | C57: =V57 -> 0 | D57: m²
A58: 6.2 | B58: Parede de gesso em placas duplas acartonado dry wall - inclusive para ambientes úmidos - RU | C58: =V58 -> 0 | D58: m²
A59: 6.3 | B59: Rasgo e fechamento em alvenaria e piso | C59: =V59 -> 0 | D59: m
A60: 7 | B60: COBERTURA
A61: 7.1 | B61: Cobertura com telha de alumínio envernizada ou pintada, e=0,5 mm | C61: =V61 -> 0 | D61: m²
A62: 7.2 | B62: Cobertura em telha com isolamento termoacustico em espuma rígida de poliuretano (PU) injetado | C62: =V62 -> 0 | D62: m²
A63: 7.3 | B63: Cumeeira em chapa metálica | C63: =V63 -> 0 | D63: m
...
