Workbook

Sheet Memorial de cálculo
A1: ITENS M² COM DESCONTO | K1: ITENS M² SEM DESCONTO | S1: ITENS M³ - ENTULHO, ETC | AA1: PINTURA ESMALTE EM PORTA | AH1: ITENS UNITÁRIOS (M, UM,
A5: Itens | K5: Itens | S5: Itens | AA5: Itens | AH5: Itens
A6: 17.6 | B6: =VLOOKUP(A6,Itens!$A$7:$J$537,2,0) -> Pintura em látex acrílica premium fosca em paredes internas ou externas, exceto muros, com três demãos, sem emassamento, com aplicação de selador para alvenaria exterior. | L6: =VLOOKUP(K6,Itens!$A$7:$J$537,2,0) -> #N/A | S6: 2.18 | T6: =VLOOKUP(S6,Itens!$A$7:$J$537,2,0) -> Remoção de entulho com caçamba metálica, inclusive limpeza, transporte, carga, descarga e descarte conforme legislação ambiental - Material de descarte (alvenaria, estruturas metálicas, madeiramento, revestimentos cerâmicos, gesso, dry-wall, entre outros) | AB6: =VLOOKUP(AA6,Itens!$A$7:$J$537,2,0) -> #N/A | AH6: 13.12 | AI6: =VLOOKUP(AH6,Itens!$A$7:$J$537,2,0) -> Deslocamento ou remanejamento de mobiliário dentro da agência
A7: Foto | B7: Comp. (m) | C7: Altura (m) | D7: Desconto (m²) | E7: Subtotal | F7: Total (m) | K7: Foto | L7: Comp. (m) | M7: Altura (m) | N7: Total (m²) | S7: Foto | T7: Comp. (m) | U7: Altura (m) | V7: Total (m³) | AA7: Foto | AB7: Comp. (m) | AC7: Altura (m) Comprimento (m) | AD7: Total (m²) | AH7: Foto | AI7: Quantitativo | AJ7: Unidade
A8: 177 | B8: 8.1 | C8: 3 | D8: 1.89 | E8: =C8*B8 -> 24.3 | F8: =E8-D8 -> 22.41 | N8: =M8*L8 -> 0 | S8: 290 | T8: 3.94 | U8: 1 | V8: =U8*T8 -> 3.94 | AC8: 2.1 | AD8: =AB8*AC8 -> 0 | AH8: 167 | AI8: 2 | AJ8: =UPPER(VLOOKUP($AH$6,Itens!$A$7:$J$537,4,0)) -> UN
E9: =C9*B9 -> 0 | F9: =E9-D9 -> 0 | N9: =M9*L9 -> 0 | V9: =U9*T9 -> 0 | AC9: 2.1 | AD9: =AB9*AC9 -> 0 | AJ9: =UPPER(VLOOKUP($AH$6,Itens!$A$7:$J$537,4,0)) -> UN
E10: =C10*B10 -> 0 | F10: =E10-D10 -> 0 | N10: =M10*L10 -> 0 | V10: =U10*T10 -> 0 | AC10: 2.1 | AD10: =AB10*AC10 -> 0 | AJ10: =UPPER(VLOOKUP($AH$6,Itens!$A$7:$J$537,4,0)) -> UN
E11: =C11*B11 -> 0 | F11: =E11-D11 -> 0 | N11: =M11*L11 -> 0 | V11: =U11*T11 -> 0 | AC11: 2.1 | AD11: =AB11*AC11 -> 0 | AJ11: =UPPER(VLOOKUP($AH$6,Itens!$A$7:$J$537,4,0)) -> UN
E12: =C12*B12 -> 0 | F12: =E12-D12 -> 0 | N12: =M12*L12 -> 0 | V12: =U12*T12 -> 0 | AC12: 2.1 | AD12: =AB12*AC12 -> 0 | AJ12: =UPPER(VLOOKUP($AH$6,Itens!$A$7:$J$537,4,0)) -> UN
E13: =C13*B13 -> 0 | F13: =E13-D13 -> 0 | N13: =M13*L13 -> 0 | V13: =U13*T13 -> 0 | AC13: 2.1 | AD13: =AB13*AC13 -> 0 | AJ13: =UPPER(VLOOKUP($AH$6,Itens!$A$7:$J$537,4,0)) -> UN
E14: =C14*B14 -> 0 | F14: =E14-D14 -> 0 | N14: =M14*L14 -> 0 | V14: =U14*T14 -> 0 | AC14: 2.1 | AD14: =AB14*AC14 -> 0 | AJ14: =UPPER(VLOOKUP($AH$6,Itens!$A$7:$J$537,4,0)) -> UN
E15: =C15*B15 -> 0 | F15: =E15-D15 -> 0 | N15: =M15*L15 -> 0 | V15: =U15*T15 -> 0 | AC15: 2.1 | AD15: =AB15*AC15 -> 0 | AJ15: =UPPER(VLOOKUP($AH$6,Itens!$A$7:$J$537,4,0)) -> UN
E16: =C16*B16 -> 0 | F16: =E16-D16 -> 0 | N16: =M16*L16 -> 0 | V16: =U16*T16 -> 0 | AC16: 2.1 | AD16: =AB16*AC16 -> 0 | AJ16: =UPPER(VLOOKUP($AH$6,Itens!$A$7:$J$537,4,0)) -> UN
E17: =C17*B17 -> 0 | F17: =E17-D17 -> 0 | N17: =M17*L17 -> 0 | V17: =U17*T17 -> 0 | AC17: 2.1 | AD17: =AB17*AC17 -> 0 | AJ17: =UPPER(VLOOKUP($AH$6,Itens!$A$7:$J$537,4,0)) -> UN
E18: =C18*B18 -> 0 | F18: =E18-D18 -> 0 | N18: =M18*L18 -> 0 | V18: =U18*T18 -> 0 | AC18: 2.1 | AD18: =AB18*AC18 -> 0 | AJ18: =UPPER(VLOOKUP($AH$6,Itens!$A$7:$J$537,4,0)) -> UN
E19: =C19*B19 -> 0 | F19: =E19-D19 -> 0 | N19: =M19*L19 -> 0 | V19: =U19*T19 -> 0 | AC19: 2.1 | AD19: =AB19*AC19 -> 0 | AJ19: =UPPER(VLOOKUP($AH$6,Itens!$A$7:$J$537,4,0)) -> UN
E20: =C20*B20 -> 0 | F20: =E20-D20 -> 0 | N20: =M20*L20 -> 0 | V20: =U20*T20 -> 0 | AC20: 2.1 | AD20: =AB20*AC20 -> 0 | AJ20: =UPPER(VLOOKUP($AH$6,Itens!$A$7:$J$537,4,0)) -> UN
... E39: =C39*B39 -> 0 | F39: =E39-D39 -> 0 | N39: =M39*L39 -> 0 | V39: =U39*T39 -> 0 | AC39: 2.1 | AD39: =AB39*AC39 -> 0 | AJ39: =UPPER(VLOOKUP($AH$6,Itens!$A$7:$J$537,4,0)) -> UN
A40: Total | F40: =SUM(F8:F39) -> 22.41 | K40: Total | N40: =SUM(N8:N39) -> 0 | S40: Total (dividido por 10) | V40: =SUM(V8:V39)/10 -> 0.394 | AA40: Total (X3) | AD40: =SUM(AD8:AD39)*3 -> 0 | AH40: Total | AI40: =SUM(AI8:AI39) -> 2 | AJ40: =UPPER(AJ8) -> UN

Sheet Itens
B1: A interessada deverá prrencher os campos em amarelo abaixo.
C3: CONSERVAÇÃO PREDIAL | M3: Informar nos campos em amarelo abaixo o desconto para MA e MO. Poderá ser informado desconto diferente ou igual para MA e MO de forma a ajustar o desconto global ao desconto ofertado na licitação. O campo em verde, após o preenchimento do MA, MO e BDI (em sua respectiva aba), deverá refletir o valor de desconto ofertado na Licitação. O valor efetivo de desconto de MA e MO considerando BDI aparecerá nos campos em Azul.
B4: PROPONENTE : | G4: LOTE: | H4: 04 | M4: Material sem BDI | N4: Mão de obra sem BDI
B5: MAFFENG ENGENHARIA E MANUTENÇÃO LTDA | C5: CNPJ: | D5: 33.624.704/0001-94 | I5: DESCONTO: | J5: 0.3114 | M5: 0.2001 | N5: 0.2001 | V5: Não mexer nos dados abaixo. Dados Sem BDI. | AB5: Não mexer nos dados abaixo. Dados com BDI. | AH5: Descontos Calculados
A7: ITEM | C7: QTDE | D7: UN. | E7: UNITÁRIO MATERIAL | F7: UNITÁRIO MÃO DE OBRA | G7: TOTAL UNITÁRIO DO ITEM | H7: TOTAL MATERIAL ROTEIRO | I7: TOTAL MÃO DE OBRA ROTEIRO | J7: TOTAL GERAL ROTEIRO | M7: Desconto Global Calculado com BDI | N7: =1-(J537/AF537) -> -0.14969529 | V7: QTDE | W7: UN. | X7: UNITÁRIO MATERIAL Referência | Y7: UNITÁRIO MÃO DE OBRA Referência | Z7: TOTAL UNITÁRIO DO ITEM Referência | AB7: QTDE | AC7: UN. | AD7: UNITÁRIO MATERIAL Referência | AE7: UNITÁRIO MÃO DE OBRA Referência | AF7: TOTAL UNITÁRIO DO ITEM Referência | AH7: UNITÁRIO MATERIAL Referência | AI7: UNITÁRIO MÃO DE OBRA Referência | AJ7: TOTAL UNITÁRIO DO ITEM Referência
A8: 1 | B8: PRELIMINARES | H8: 805267.07 | I8: 312423.9 | J8: 1117691 | M8: O valor do campo em verde deverá ser igual ao da proposta apresentada.
A9: 1.1 | B9: Chamado | C9: 249 | D9: un | E9: 0 | F9: 86.69 | G9: 86.69 | H9: 0 | I9: 21585.81 | J9: 21585.81 | V9: 392 | W9: un | X9: 0 | Y9: 106.2 | Z9: =SUM(X9:Y9) -> 106.2 | AB9: 392 | AC9: un | AD9: 0 | AE9: 135.41 | AF9: =SUM(AD9:AE9) -> 135.41 | AH9: =IF(E9=0,0,(E9/AD9)-1) -> 0 | AI9: =IF(F9=0,0,(F9/AE9)-1) -> -0.35979617 | AJ9: =IF(G9=0,0,(G9/AF9)-1) -> -0.35979617
A10: 1.2 | B10: Deslocamento | C10: 299981 | D10: km | E10: 1.66 | F10: 0.73 | G10: 2.39 | H10: 497968.46 | I10: 218986.13 | J10: 716954.59 | V10: 200480 | W10: km | X10: 1.89 | Y10: 0.97 | Z10: =SUM(X10:Y10) -> 2.86 | AB10: 200480 | AC10: km | AD10: 2.41 | AE10: 1.24 | AF10: =SUM(AD10:AE10) -> 3.65 | AH10: =IF(E10=0,0,(E10/AD10)-1) -> -0.31120332 | AI10: =IF(F10=0,0,(F10/AE10)-1) -> -0.41129032 | AJ10: =IF(G10=0,0,(G10/AF10)-1) -> -0.34520548
A11: 1.3 | B11: Revisão de instalações | C11: 151 | D11: un | E11: 87.3 | F11: 468.71 | G11: 556.01 | H11: 13182.3 | I11: 70775.21 | J11: 83957.51 | V11: 168 | W11: un | X11: 99.64 | Y11: 430.84 | Z11: =SUM(X11:Y11) -> 530.48 | AB11: 168 | AC11: un | AD11: 127.04 | AE11: 549.32 | AF11: =SUM(AD11:AE11) -> 676.36 | AH11: =IF(E11=0,0,(E11/AD11)-1) -> -0.31281486 | AI11: =IF(F11=0,0,(F11/AE11)-1) -> -0.14674507 | AJ11: =IF(G11=0,0,(G11/AF11)-1) -> -0.17793778
A12: 1.4 | B12: Acompanhamento técnico em Segurança do Trabalho | C12: 1 | D12: un | E12: 0 | F12: 442.2 | G12: 442.2 | H12: 0 | I12: 442.2 | J12: 442.2 | V12: 40 | W12: un | X12: 0 | Y12: 285.92 | Z12: =SUM(X12:Y12) -> 285.92 | AB12: 40 | AC12: un | AD12: 0 | AE12: 364.55 | AF12: =SUM(AD12:AE12) -> 364.55 | AH12: =IF(E12=0,0,(E12/AD12)-1) -> 0 | AI12: =IF(F12=0,0,(F12/AE12)-1) -> 0.21300233 | AJ12: =IF(G12=0,0,(G12/AF12)-1) -> 0.21300233
A13: 1.5 | B13: Hospedagem de equipe técnica - Serviços prolongados | C13: 151 | D13: un | E13: 1947.18 | F13: 0 | G13: 1947.18 | H13: 294024.18 | I13: 0 | J13: 294024.18 | V13: 56 | W13: un | X13: 2222.54 | Y13: 0 | Z13: =SUM(X13:Y13) -> 2222.54 | AB13: 56 | AC13: un | AD13: 2833.74 | AE13: 0 | AF13: =SUM(AD13:AE13) -> 2833.74 | AH13: =IF(E13=0,0,(E13/AD13)-1) -> -0.31285862 | AI13: =IF(F13=0,0,(F13/AE13)-1) -> 0 | AJ13: =IF(G13=0,0,(G13/AF13)-1) -> -0.31285862
A14: 1.6 | B14: Deslocamento Fluvial | C14: 2 | D14: Km | E14: 0.82 | F14: 1.79 | G14: 2.61 | H14: 1.64 | I14: 3.58 | J14: 5.22 | M14: Desconto Calculado Material Efetivo | N14: =IF(M5=0,0,ROUND(AH540,4)) -> -0.3141 | V14: 1 | W14: Km | X14: 0.94 | Y14: 2.02 | Z14: =SUM(X14:Y14) -> 2.96 | AB14: 1 | AC14: Km | AD14: 1.2 | AE14: 2.58 | AF14: =SUM(AD14:AE14) -> 3.78 | AH14: =IF(E14=0,0,(E14/AD14)-1) -> -0.31666667 | AI14: =IF(F14=0,0,(F14/AE14)-1) -> -0.30620155 | AJ14: =IF(G14=0,0,(G14/AF14)-1) -> -0.30952381
A15: 1.7 | B15: Laudo técnico fotográfico - Elementos de Sinalização - Padrão BB | C15: 1 | D15: UN | E15: 90.49 | F15: 630.97 | G15: 721.46 | H15: 90.49 | I15: 630.97 | J15: 721.46 | M15: Desconto Calculado Mão de Obra Efetivo | N15: =IF(N5=0,0,ROUND(AI540,4)) -> -0.0901 | V15: 1 | W15: UN | X15: 103.29 | Y15: 734.85 | Z15: =SUM(X15:Y15) -> 838.14 | AB15: 1 | AC15: UN | AD15: 131.69 | AE15: 936.93 | AF15: =SUM(AD15:AE15) -> 1068.62 | AH15: =IF(E15=0,0,(E15/AD15)-1) -> -0.31285595 | AI15: =IF(F15=0,0,(F15/AE15)-1) -> -0.32655588 | AJ15: =IF(G15=0,0,(G15/AF15)-1) -> -0.32486759
A16: 2 | B16: IMPLANTAÇÃO / ADMINISTRAÇÃO | H16: 158849.08 | I16: 206579.93 | J16: 365429.01 | M16: Os valores acima consideram o valor informado na aba BDI. | AH16: =IF(E16=0,0,(E16/AD16)-1) -> 0 | AI16: =IF(F16=0,0,(F16/AE16)-1) -> 0 | AJ16: =IF(G16=0,0,(G16/AF16)-1) -> 0
A17: 2.1 | B17: Demolição manual de concreto simples | C17: 27 | D17: m³ | E17: 0 | F17: 347.88 | G17: 347.88 | H17: 0 | I17: 9392.76 | J17: 9392.76 | V17: 7 | W17: m³ | X17: 0 | Y17: 288.91 | Z17: =SUM(X17:Y17) -> 288.91 | AB17: 7 | AC17: m³ | AD17: 0 | AE17: 368.36 | AF17: =SUM(AD17:AE17) -> 368.36 | AH17: =IF(E17=0,0,(E17/AD17)-1) -> 0 | AI17: =IF(F17=0,0,(F17/AE17)-1) -> -0.055597785 | AJ17: =IF(G17=0,0,(G17/AF17)-1) -> -0.055597785
A18: 2.2 | B18: Demolição manual de alvenaria de elevação ou elemento vazado, incluindo revestimento | C18: 51 | D18: m³ | E18: 0 | F18: 80.28 | G18: 80.28 | H18: 0 | I18: 4094.28 | J18: 4094.28 | M18: A interessada pode alterar o BDI na respectiva aba da planilha eletrônica. A alteração do BDI afeta o desconto calculado efetivo de material e de mão de obra. O valor do BDI deverá ser igual ao da proposta a ser apresentada. | V18: 23 | W18: m³ | X18: 0 | Y18: 66.67 | Z18: =SUM(X18:Y18) -> 66.67 | AB18: 23 | AC18: m³ | AD18: 0 | AE18: 85 | AF18: =SUM(AD18:AE18) -> 85 | AH18: =IF(E18=0,0,(E18/AD18)-1) -> 0 | AI18: =IF(F18=0,0,(F18/AE18)-1) -> -0.055529412 | AJ18: =IF(G18=0,0,(G18/AF18)-1) -> -0.055529412
A19: 2.3 | B19: Demolição manual de revestimento em massa de parede ou teto ou Dry-Wall | C19: 362 | D19: m³ | E19: 0 | F19: 8.52 | G19: 8.52 | H19: 0 | I19: 3084.24 | J19: 3084.24 | V19: 116 | W19: m³ | X19: 0 | Y19: 7.43 | Z19: =SUM(X19:Y19) -> 7.43 | AB19: 116 | AC19: m³ | AD19: 0 | AE19: 9.47 | AF19: =SUM(AD19:AE19) -> 9.47 | AH19: =IF(E19=0,0,(E19/AD19)-1) -> 0 | AI19: =IF(F19=0,0,(F19/AE19)-1) -> -0.10031679 | AJ19: =IF(G19=0,0,(G19/AF19)-1) -> -0.10031679
A20: 2.4 | B20: Demolição de pisos em geral (ladrilho hidráulico, camada de enchimento, cerâmica, porcelanato, mármore, granito, pedra e madeira) - Manual | C20: 293 | D20: m² | E20: 0 | F20: 37.46 | G20: 37.46 | H20: 0 | I20: 10975.78 | J20: 10975.78 | V20: 35 | W20: m² | X20: 0 | Y20: 31.11 | Z20: =SUM(X20:Y20) -> 31.11 | AB20: 35 | AC20: m² | AD20: 0 | AE20: 39.67 | AF20: =SUM(AD20:AE20) -> 39.67 | AH20: =IF(E20=0,0,(E20/AD20)-1) -> 0 | AI20: =IF(F20=0,0,(F20/AE20)-1) -> -0.055709604 | AJ20: =IF(G20=0,0,(G20/AF20)-1) -> -0.055709604
A21: 2.5 | B21: Demolição de pisos em geral (ladrilho hidráulico, camada de enchimento, cerâmica, porcelanato, mármore, granito, pedra e madeira) - Mecanizado | C21: 139 | D21: m² | E21: 26.28 | F21: 18.73 | G21: 45.01 | H21: 3652.92 | I21: 2603.47 | J21: 6256.39 | V21: 73 | W21: m² | X21: 23.22 | Y21: 15.56 | Z21: =SUM(X21:Y21) -> 38.78 | AB21: 73 | AC21: m² | AD21: 29.61 | AE21: 19.84 | AF21: =SUM(AD21:AE21) -> 49.45 | AH21: =IF(E21=0,0,(E21/AD21)-1) -> -0.11246201 | AI21: =IF(F21=0,0,(F21/AE21)-1) -> -0.055947581 | AJ21: =IF(G21=0,0,(G21/AF21)-1) -> -0.089787664
A22: 2.6 | B22: Demolição de pavimentação com pré-moldado de concreto ou intertravado | C22: 6 | D22: m² | E22: 0 | F22: 18.73 | G22: 18.73 | H22: 0 | I22: 112.38 | J22: 112.38 | V22: 1 | W22: m² | X22: 0 | Y22: 15.56 | Z22: =SUM(X22:Y22) -> 15.56 | AB22: 1 | AC22: m² | AD22: 0 | AE22: 19.84 | AF22: =SUM(AD22:AE22) -> 19.84 | AH22: =IF(E22=0,0,(E22/AD22)-1) -> 0 | AI22: =IF(F22=0,0,(F22/AE22)-1) -> -0.055947581 | AJ22: =IF(G22=0,0,(G22/AF22)-1) -> -0.055947581
A23: 2.7 | B23: Demolição de piso cimentado sobre lastro de concreto | C23: 35 | D23: m² | E23: 0 | F23: 34.79 | G23: 34.79 | H23: 0 | I23: 1217.65 | J23: 1217.65 | V23: 1 | W23: m² | X23: 0 | Y23: 28.89 | Z23: =SUM(X23:Y23) -> 28.89 | AB23: 1 | AC23: m² | AD23: 0 | AE23: 36.83 | AF23: =SUM(AD23:AE23) -> 36.83 | AH23: =IF(E23=0,0,(E23/AD23)-1) -> 0 | AI23: =IF(F23=0,0,(F23/AE23)-1) -> -0.055389628 | AJ23: =IF(G23=0,0,(G23/AF23)-1) -> -0.055389628
A24: 2.8 | B24: Demolição manual de forro, inclusive sistema de fixação/tarugamento | C24: 939 | D24: m² | E24: 0 | F24: 10.71 | G24: 10.71 | H24: 0 | I24: 10056.69 | J24: 10056.69 | M24: A interessada pode utilizar modelo próprio de planilha para cálculo,entretanto,a planilha final a ser apresentada juntamente com a proposta, deverá ter a mesma formatação do orçamento estimado que compõe a licitação. | V24: 850 | W24: m² | X24: 0 | Y24: 8.89 | Z24: =SUM(X24:Y24) -> 8.89 | AB24: 850 | AC24: m² | AD24: 0 | AE24: 11.33 | AF24: =SUM(AD24:AE24) -> 11.33 | AH24: =IF(E24=0,0,(E24/AD24)-1) -> 0 | AI24: =IF(F24=0,0,(F24/AE24)-1) -> -0.054721977 | AJ24: =IF(G24=0,0,(G24/AF24)-1) -> -0.054721977
A25: 2.9 | B25: Demolição de contrapiso/argamassa regularizante, isolante ou protetora | C25: 203 | D25: m² | E25: 0 | F25: 13.38 | G25: 13.38 | H25: 0 | I25: 2716.14 | J25: 2716.14 | V25: 6 | W25: m² | X25: 0 | Y25: 11.11 | Z25: =SUM(X25:Y25) -> 11.11 | AB25: 6 | AC25: m² | AD25: 0 | AE25: 14.17 | AF25: =SUM(AD25:AE25) -> 14.17 | AH25: =IF(E25=0,0,(E25/AD25)-1) -> 0 | AI25: =IF(F25=0,0,(F25/AE25)-1) -> -0.055751588 | AJ25: =IF(G25=0,0,(G25/AF25)-1) -> -0.055751588
A26: 2.10 | B26: Demolição de estrutura em madeira para telhado | C26: 61 | D26: m² | E26: 0 | F26: 36.98 | G26: 36.98 | H26: 0 | I26: 2255.78 | J26: 2255.78 | V26: 1 | W26: m² | X26: 0 | Y26: 31.33 | Z26: =SUM(X26:Y26) -> 31.33 | AB26: 1 | AC26: m² | AD26: 0 | AE26: 39.95 | AF26: =SUM(AD26:AE26) -> 39.95 | AH26: =IF(E26=0,0,(E26/AD26)-1) -> 0 | AI26: =IF(F26=0,0,(F26/AE26)-1) -> -0.074342929 | AJ26: =IF(G26=0,0,(G26/AF26)-1) -> -0.074342929
A27: 2.11 | B27: Retirada de cumeeira, espigão, rufo, calha ou chapim, perfil qualquer | C27: 152 | D27: m | E27: 0 | F27: 17.27 | G27: 17.27 | H27: 0 | I27: 2625.04 | J27: 2625.04 | V27: 203 | W27: m | X27: 0 | Y27: 15.47 | Z27: =SUM(X27:Y27) -> 15.47 | AB27: 203 | AC27: m | AD27: 0 | AE27: 19.72 | AF27: =SUM(AD27:AE27) -> 19.72 | AH27: =IF(E27=0,0,(E27/AD27)-1) -> 0 | AI27: =IF(F27=0,0,(F27/AE27)-1) -> -0.12423935 | AJ27: =IF(G27=0,0,(G27/AF27)-1) -> -0.12423935
A28: 2.12 | B28: Retirada de piso tátil com limpeza | C28: 814 | D28: m² | E28: 11.07 | F28: 28.13 | G28: 39.2 | H28: 9010.98 | I28: 22897.82 | J28: 31908.8 | V28: 3400 | W28: m² | X28: 19.61 | Y28: 25.1 | Z28: =SUM(X28:Y28) -> 44.71 | AB28: 3400 | AC28: m² | AD28: 25 | AE28: 32 | AF28: =SUM(AD28:AE28) -> 57 | AH28: =IF(E28=0,0,(E28/AD28)-1) -> -0.5572 | AI28: =IF(F28=0,0,(F28/AE28)-1) -> -0.1209375 | AJ28: =IF(G28=0,0,(G28/AF28)-1) -> -0.3122807
A29: 2.13 | B29: Remoção de revestimento de piso de carpete ou manta vinílica | C29: 2344 | D29: m² | E29: 11.07 | F29: 14.23 | G29: 25.3 | H29: 25948.08 | I29: 33355.12 | J29: 59303.2 | V29: 1913 | W29: m² | X29: 19.61 | Y29: 12.91 | Z29: =SUM(X29:Y29) -> 32.52 | AB29: 1913 | AC29: m² | AD29: 25 | AE29: 16.46 | AF29: =SUM(AD29:AE29) -> 41.46 | AH29: =IF(E29=0,0,(E29/AD29)-1) -> -0.5572 | AI29: =IF(F29=0,0,(F29/AE29)-1) -> -0.13547995 | AJ29: =IF(G29=0,0,(G29/AF29)-1) -> -0.38977328
A30: 2.14 | B30: Ajuste de Piso Elevado (remoção e recolocação de revestimentos e placas do piso inclusive) | C30: 72 | D30: m² | E30: 7.86 | F30: 74.09 | G30: 81.95 | H30: 565.92 | I30: 5334.48 | J30: 5900.4 | V30: 375 | W30: m² | X30: 9.93 | Y30: 66.6 | Z30: =SUM(X30:Y30) -> 76.53 | AB30: 375 | AC30: m² | AD30: 12.66 | AE30: 84.92 | AF30: =SUM(AD30:AE30) -> 97.58 | AH30: =IF(E30=0,0,(E30/AD30)-1) -> -0.37914692 | AI30: =IF(F30=0,0,(F30/AE30)-1) -> -0.12753179 | AJ30: =IF(G30=0,0,(G30/AF30)-1) -> -0.16017627
A31: 2.15 | B31: Retirada de piso elevado, inclusive estrutura de sustentação | C31: 180 | D31: m² | E31: 0 | F31: 34.13 | G31: 34.13 | H31: 0 | I31: 6143.4 | J31: 6143.4 | V31: 410 | W31: m² | X31: 0 | Y31: 28.92 | Z31: =SUM(X31:Y31) -> 28.92 | AB31: 410 | AC31: m² | AD31: 0 | AE31: 36.87 | AF31: =SUM(AD31:AE31) -> 36.87 | AH31: =IF(E31=0,0,(E31/AD31)-1) -> 0 | AI31: =IF(F31=0,0,(F31/AE31)-1) -> -0.074315161 | AJ31: =IF(G31=0,0,(G31/AF31)-1) -> -0.074315161
A32: 2.16 | B32: Reinstalação de piso elevado proveniente de reaproveitamento, incluso material | C32: 18 | D32: m² | E32: 1.55 | F32: 80.31 | G32: 81.86 | H32: 27.9 | I32: 1445.58 | J32: 1473.48 | V32: 1 | W32: m² | X32: 1.78 | Y32: 72.09 | Z32: =SUM(X32:Y32) -> 73.87 | AB32: 1 | AC32: m² | AD32: 2.27 | AE32: 91.91 | AF32: =SUM(AD32:AE32) -> 94.18 | AH32: =IF(E32=0,0,(E32/AD32)-1) -> -0.31718062 | AI32: =IF(F32=0,0,(F32/AE32)-1) -> -0.12621042 | AJ32: =IF(G32=0,0,(G32/AF32)-1) -> -0.13081334
A33: 2.17 | B33: Retirada ou recolocação de vidro | C33: 517 | D33: m² | E33: 11.3 | F33: 19.12 | G33: 30.42 | H33: 5842.1 | I33: 9885.04 | J33: 15727.14 | V33: 235 | W33: m² | X33: 26.9 | Y33: 16.45 | Z33: =SUM(X33:Y33) -> 43.35 | AB33: 235 | AC33: m² | AD33: 34.3 | AE33: 20.97 | AF33: =SUM(AD33:AE33) -> 55.27 | AH33: =IF(E33=0,0,(E33/AD33)-1) -> -0.67055394 | AI33: =IF(F33=0,0,(F33/AE33)-1) -> -0.088221268 | AJ33: =IF(G33=0,0,(G33/AF33)-1) -> -0.449611
A34: 2.18 | B34: Remoção de entulho com caçamba metálica, inclusive limpeza, transporte, carga, descarga e descarte conforme legislação ambiental - Material de descarte (alvenaria, estruturas metálicas, madeiramento, revestimentos cerâmicos, gesso, dry-wall, entre outros) | C34: 1000 | D34: m³ | E34: 55.11 | F34: 16.81 | G34: 71.92 | H34: 55110 | I34: 16810 | J34: 71920 | V34: 17 | W34: m³ | X34: 62.9 | Y34: 13.69 | Z34: =SUM(X34:Y34) -> 76.59 | AB34: 17 | AC34: m³ | AD34: 80.2 | AE34: 17.45 | AF34: =SUM(AD34:AE34) -> 97.65 | AH34: =IF(E34=0,0,(E34/AD34)-1) -> -0.31284289 | AI34: =IF(F34=0,0,(F34/AE34)-1) -> -0.036676218 | AJ34: =IF(G34=0,0,(G34/AF34)-1) -> -0.26349206
A35: 2.19 | B35: Remoção / Remanejamento de placa aérea | C35: 215 | D35: un | E35: 3.43 | F35: 51.72 | G35: 55.15 | H35: 737.45 | I35: 11119.8 | J35: 11857.25 | V35: 72 | W35: un | X35: 6.88 | Y35: 43.2 | Z35: =SUM(X35:Y35) -> 50.08 | AB35: 72 | AC35: un | AD35: 8.77 | AE35: 55.08 | AF35: =SUM(AD35:AE35) -> 63.85 | AH35: =IF(E35=0,0,(E35/AD35)-1) -> -0.60889396 | AI35: =IF(F35=0,0,(F35/AE35)-1) -> -0.061002179 | AJ35: =IF(G35=0,0,(G35/AF35)-1) -> -0.13625685
A36: 2.20 | B36: Andaime tubular fachadeiro | C36: 291 | D36: m²/mês | E36: 18.95 | F36: 8.34 | G36: 27.29 | H36: 5514.45 | I36: 2426.94 | J36: 7941.39 | V36: 1033 | W36: m²/mês | X36: 17 | Y36: 8.01 | Z36: =SUM(X36:Y36) -> 25.01 | AB36: 1033 | AC36: m²/mês | AD36: 21.68 | AE36: 10.21 | AF36: =SUM(AD36:AE36) -> 31.89 | AH36: =IF(E36=0,0,(E36/AD36)-1) -> -0.12592251 | AI36: =IF(F36=0,0,(F36/AE36)-1) -> -0.18315377 | AJ36: =IF(G36=0,0,(G36/AF36)-1) -> -0.14424585
... A52: 2.36 | B52: Tela para Andaime | C52: 1 | D52: m² | E52: 2.3 | F52: 3.79 | G52: 6.09 | H52: 2.3 | I52: 3.79 | J52: 6.09 | V52: 1 | W52: m² | X52: 2.71 | Y52: 3.44 | Z52: =SUM(X52:Y52) -> 6.15 | AB52: 1 | AC52: m² | AD52: 3.46 | AE52: 4.39 | AF52: =SUM(AD52:AE52) -> 7.85 | AH52: =IF(E52=0,0,(E52/AD52)-1) -> -0.33526012 | AI52: =IF(F52=0,0,(F52/AE52)-1) -> -0.13667426 | AJ52: =IF(G52=0,0,(G52/AF52)-1) -> -0.22420382
A53: 3 | B53: MOVIMENTO DE TERRA | H53: 2.07 | I53: 117.21 | J53: 119.28 | AH53: =IF(E53=0,0,(E53/AD53)-1) -> 0 | AI53: =IF(F53=0,0,(F53/AE53)-1) -> 0 | AJ53: =IF(G53=0,0,(G53/AF53)-1) -> 0
A54: 3.1 | B54: Escavação Manual em Solo | C54: 1 | D54: m³ | E54: 0 | F54: 96.06 | G54: 96.06 | H54: 0 | I54: 96.06 | J54: 96.06 | V54: 1 | W54: m³ | X54: 0 | Y54: 78.2 | Z54: =SUM(X54:Y54) -> 78.2 | AB54: 1 | AC54: m³ | AD54: 0 | AE54: 99.71 | AF54: =SUM(AD54:AE54) -> 99.71 | AH54: =IF(E54=0,0,(E54/AD54)-1) -> 0 | AI54: =IF(F54=0,0,(F54/AE54)-1) -> -0.036606158 | AJ54: =IF(G54=0,0,(G54/AF54)-1) -> -0.036606158
A55: 3.2 | B55: Reaterro/Aterro Manual de Solo | C55: 1 | D55: m³ | E55: 2.07 | F55: 21.15 | G55: 23.22 | H55: 2.07 | I55: 21.15 | J55: 23.22 | V55: 1 | W55: m³ | X55: 2.3 | Y55: 17.22 | Z55: =SUM(X55:Y55) -> 19.52 | AB55: 1 | AC55: m³ | AD55: 2.93 | AE55: 21.96 | AF55: =SUM(AD55:AE55) -> 24.89 | AH55: =IF(E55=0,0,(E55/AD55)-1) -> -0.29351536 | AI55: =IF(F55=0,0,(F55/AE55)-1) -> -0.036885246 | AJ55: =IF(G55=0,0,(G55/AF55)-1) -> -0.067095219
A56: 4 | B56: FUNDAÇÃO | H56: 0 | I56: 0 | J56: 0 | AH56: =IF(E56=0,0,(E56/AD56)-1) -> 0 | AI56: =IF(F56=0,0,(F56/AE56)-1) -> 0 | AJ56: =IF(G56=0,0,(G56/AF56)-1) -> 0
A57: 5 | B57: ESTRUTURA | H57: 17598.69 | I57: 6394.02 | J57: 23992.71 | AH57: =IF(E57=0,0,(E57/AD57)-1) -> 0 | AI57: =IF(F57=0,0,(F57/AE57)-1) -> 0 | AJ57: =IF(G57=0,0,(G57/AF57)-1) -> 0
...
