Workbook

Sheet RAT 
A1: RAT - RELATÓRIO DE ATENDIMENTO
A2: EXECUÇÃO DOS SERVIÇOS
A3: Número da solicitação | C3: Data/hora Abertura | F3: Contrato de Manutenção | I3: Contratada
F4: 2024.7421.6122 | I4: MAFFENG ENGENHARIA E MANUTENÇÃO
A5: Sinistro | C5: Prazo de atendimento | F5: Tipo de Manutenção | I5: Nível de Ocorrência
A6: (Sim/Não) | F6: (Preventiva/Corretiva) | I6: (Emergencial/Urgente/Normal)
A7: Não | F7: Preventiva | I7: Normal
A8: Prefixo / SB - Dependência Beneficiada | F8: Endereço
B9: =IFERROR(UPPER(VLOOKUP(A9,Prefixos!A5:E69,2,0)),"") | F9: =IFERROR(UPPER(VLOOKUP(A9,Prefixos!A5:E69,5,0)),"")
A10: Informações de Contato | F10: Matrícula / Nome - Funcionário Solicitante
A11: Responsável | F11: F2190439 - SISTEMA
A12: SERVIÇOS SOLICITADOS - Portal de Manutenção
A13: Descrição do serviço, Tipo, Quantidade, Local de Atendimento e Prioridade* | J13: Situação (Código**)
A14: Levantamento Preventivo | J14: 4
A15: * Preencher com as informações do Portal de Manutenção da DISEC. ** Preencher o campo situação com os códigos a seguir: 1. Serviço concluído sem pendências; 2. Serviço cancelado pelo demandante; 3. Atendimento Parcial; 4. Confecção de orçamento, para execução do serviço demanda autorização por parte do CESUP Suprimentos; 5. Não Atendido. 6. Mitigação de Riscos ou primeiro atendimento
A16: ORÇAMENTO DOS SERVIÇOS REALIZADOS
A17: ITEM | B17: DESCRIÇÃO | H17: QTD. | I17: UND. | J17: VALOR UNITÁRIO | L17: MAT UNIT | M17: MAO. UNIT | N17: MAT TOTAL | O17: MAO TOTAL | P17: VALOR TOTAL
A18: 1.2 | B18: =IFERROR(UPPER(VLOOKUP(A18,Tabela3[#All],2,0)),"") -> DESLOCAMENTO | I18: =IFERROR(VLOOKUP(A18,Tabela3[#All],4,0),"") -> km | J18: =IFERROR(VLOOKUP(A18,Tabela3[#All],7,0),"") -> 2.6 | L18: =IFERROR(VLOOKUP(A18,Tabela3[#All],5,0),"") -> 2.12 | M18: =IFERROR(VLOOKUP(A18,Tabela3[#All],6,0),"") -> 0.48 | N18: =L18*H18 -> 0 | O18: =M18*H18 -> 0 | P18: =IFERROR(J18*H18,"") -> 0
B19: =IFERROR(UPPER(VLOOKUP(A19,Tabela3[#All],2,0)),"") | I19: =IFERROR(VLOOKUP(A19,Tabela3[#All],4,0),"") | J19: =IFERROR(VLOOKUP(A19,Tabela3[#All],7,0),"") | L19: =IFERROR(VLOOKUP(A19,Tabela3[#All],5,0),"") | M19: =IFERROR(VLOOKUP(A19,Tabela3[#All],6,0),"") | N19: =L19*H19 -> #VALUE! | O19: =M19*H19 -> #VALUE! | P19: =IFERROR(J19*H19,"")
B20: =IFERROR(UPPER(VLOOKUP(A20,Tabela3[#All],2,0)),"") | I20: =IFERROR(VLOOKUP(A20,Tabela3[#All],4,0),"") | J20: =IFERROR(VLOOKUP(A20,Tabela3[#All],7,0),"") | L20: =IFERROR(VLOOKUP(A20,Tabela3[#All],5,0),"") | M20: =IFERROR(VLOOKUP(A20,Tabela3[#All],6,0),"") | N20: =L20*H20 -> #VALUE! | O20: =M20*H20 -> #VALUE! | P20: =IFERROR(J20*H20,"")
B21: =IFERROR(UPPER(VLOOKUP(A21,Tabela3[#All],2,0)),"") | I21: =IFERROR(VLOOKUP(A21,Tabela3[#All],4,0),"") | J21: =IFERROR(VLOOKUP(A21,Tabela3[#All],7,0),"") | L21: =IFERROR(VLOOKUP(A21,Tabela3[#All],5,0),"") | M21: =IFERROR(VLOOKUP(A21,Tabela3[#All],6,0),"") | N21: =L21*H21 -> #VALUE! | O21: =M21*H21 -> #VALUE! | P21: =IFERROR(J21*H21,"")
B22: =IFERROR(UPPER(VLOOKUP(A22,Tabela3[#All],2,0)),"") | I22: =IFERROR(VLOOKUP(A22,Tabela3[#All],4,0),"") | J22: =IFERROR(VLOOKUP(A22,Tabela3[#All],7,0),"") | L22: =IFERROR(VLOOKUP(A22,Tabela3[#All],5,0),"") | M22: =IFERROR(VLOOKUP(A22,Tabela3[#All],6,0),"") | N22: =L22*H22 -> #VALUE! | O22: =M22*H22 -> #VALUE! | P22: =IFERROR(J22*H22,"")
B23: =IFERROR(UPPER(VLOOKUP(A23,Tabela3[#All],2,0)),"") | I23: =IFERROR(VLOOKUP(A23,Tabela3[#All],4,0),"") | J23: =IFERROR(VLOOKUP(A23,Tabela3[#All],7,0),"") | L23: =IFERROR(VLOOKUP(A23,Tabela3[#All],5,0),"") | M23: =IFERROR(VLOOKUP(A23,Tabela3[#All],6,0),"") | N23: =L23*H23 -> #VALUE! | O23: =M23*H23 -> #VALUE! | P23: =IFERROR(J23*H23,"")
B24: =IFERROR(UPPER(VLOOKUP(A24,Tabela3[#All],2,0)),"") | I24: =IFERROR(VLOOKUP(A24,Tabela3[#All],4,0),"") | J24: =IFERROR(VLOOKUP(A24,Tabela3[#All],7,0),"") | L24: =IFERROR(VLOOKUP(A24,Tabela3[#All],5,0),"") | M24: =IFERROR(VLOOKUP(A24,Tabela3[#All],6,0),"") | N24: =L24*H24 -> #VALUE! | O24: =M24*H24 -> #VALUE! | P24: =IFERROR(J24*H24,"")
B25: =IFERROR(UPPER(VLOOKUP(A25,Tabela3[#All],2,0)),"") | I25: =IFERROR(VLOOKUP(A25,Tabela3[#All],4,0),"") | J25: =IFERROR(VLOOKUP(A25,Tabela3[#All],7,0),"") | L25: =IFERROR(VLOOKUP(A25,Tabela3[#All],5,0),"") | M25: =IFERROR(VLOOKUP(A25,Tabela3[#All],6,0),"") | N25: =L25*H25 -> #VALUE! | O25: =M25*H25 -> #VALUE! | P25: =IFERROR(J25*H25,"")
B26: =IFERROR(UPPER(VLOOKUP(A26,Tabela3[#All],2,0)),"") | I26: =IFERROR(VLOOKUP(A26,Tabela3[#All],4,0),"") | J26: =IFERROR(VLOOKUP(A26,Tabela3[#All],7,0),"") | L26: =IFERROR(VLOOKUP(A26,Tabela3[#All],5,0),"") | M26: =IFERROR(VLOOKUP(A26,Tabela3[#All],6,0),"") | N26: =L26*H26 -> #VALUE! | O26: =M26*H26 -> #VALUE! | P26: =IFERROR(J26*H26,"")
B27: =IFERROR(UPPER(VLOOKUP(A27,Tabela3[#All],2,0)),"") | I27: =IFERROR(VLOOKUP(A27,Tabela3[#All],4,0),"") | J27: =IFERROR(VLOOKUP(A27,Tabela3[#All],7,0),"") | L27: =IFERROR(VLOOKUP(A27,Tabela3[#All],5,0),"") | M27: =IFERROR(VLOOKUP(A27,Tabela3[#All],6,0),"") | N27: =L27*H27 -> #VALUE! | O27: =M27*H27 -> #VALUE! | P27: =IFERROR(J27*H27,"")
B28: =IFERROR(UPPER(VLOOKUP(A28,Tabela3[#All],2,0)),"") | I28: =IFERROR(VLOOKUP(A28,Tabela3[#All],4,0),"") | J28: =IFERROR(VLOOKUP(A28,Tabela3[#All],7,0),"") | L28: =IFERROR(VLOOKUP(A28,Tabela3[#All],5,0),"") | M28: =IFERROR(VLOOKUP(A28,Tabela3[#All],6,0),"") | N28: =L28*H28 -> #VALUE! | O28: =M28*H28 -> #VALUE! | P28: =IFERROR(J28*H28,"")
B29: =IFERROR(UPPER(VLOOKUP(A29,Tabela3[#All],2,0)),"") | I29: =IFERROR(VLOOKUP(A29,Tabela3[#All],4,0),"") | J29: =IFERROR(VLOOKUP(A29,Tabela3[#All],7,0),"") | L29: =IFERROR(VLOOKUP(A29,Tabela3[#All],5,0),"") | M29: =IFERROR(VLOOKUP(A29,Tabela3[#All],6,0),"") | N29: =L29*H29 -> #VALUE! | O29: =M29*H29 -> #VALUE! | P29: =IFERROR(J29*H29,"")
B30: =IFERROR(UPPER(VLOOKUP(A30,Tabela3[#All],2,0)),"") | I30: =IFERROR(VLOOKUP(A30,Tabela3[#All],4,0),"") | J30: =IFERROR(VLOOKUP(A30,Tabela3[#All],7,0),"") | L30: =IFERROR(VLOOKUP(A30,Tabela3[#All],5,0),"") | M30: =IFERROR(VLOOKUP(A30,Tabela3[#All],6,0),"") | N30: =L30*H30 -> #VALUE! | O30: =M30*H30 -> #VALUE! | P30: =IFERROR(J30*H30,"")
... B57: =IFERROR(UPPER(VLOOKUP(A57,Tabela3[#All],2,0)),"") | I57: =IFERROR(VLOOKUP(A57,Tabela3[#All],4,0),"") | J57: =IFERROR(VLOOKUP(A57,Tabela3[#All],7,0),"") | L57: =IFERROR(VLOOKUP(A57,Tabela3[#All],5,0),"") | M57: =IFERROR(VLOOKUP(A57,Tabela3[#All],6,0),"") | N57: =L57*H57 -> #VALUE! | O57: =M57*H57 -> #VALUE! | P57: =IFERROR(J57*H57,"")
A58: RESUMO DO ORÇAMENTO DOS SERVIÇOS SOLICITADOS
A59: Data / Hora Conclusão | F59: Valor de Materiais + Mão de Obra | I59: Valor Total
A60: =E75 -> 0 | F60: =SUM(N18:N57) -> #VALUE! | G60: + | H60: =SUM(O18:O57) -> #VALUE! | I60: =H60+F60 -> #VALUE!
A61: Observações
B65: ________________________________________________ | H65: ___________________________________________________________________________________
B69: VISTO REPRESENTANTE DA EMPRESA CONTRATADA | H69: CARIMBO E VISTO DA DEPENDÊNCIA
A71: TÉCNICO | I71: ENGENHEIRO
A72: Laura
A73: AUXILIAR
...

Sheet Conformidade
A1: RAT - RELATÓRIO DE ATENDIMENTO
A2: Conformidade do atendimento no local dos serviços
A3: Número da solicitação | C3: Data/hora Abertura | F3: Contrato de Manutenção | I3: Contratada
A4: ='RAT '!A4 -> 0 | C4: ='RAT '!C4 -> 0 | F4: 2024.7421.6122 | I4: MAFFENG ENGENHARIA E MANUTENÇÃO
A5: Sinistro | C5: Prazo de atendimento | F5: Tipo de Manutenção | I5: Nível de Ocorrência
A6: (Sim/Não) | F6: (Preventiva/Corretiva) | I6: (Emergencial/Urgente/Normal)
A7: ='RAT '!A7 -> Não | C7: ='RAT '!C7 -> 0 | F7: ='RAT '!F7 -> Preventiva | I7: ='RAT '!I7 -> Normal
A8: Prefixo / SB - Dependência Beneficiada | F8: Endereço
A9: ='RAT '!A9 -> 0 | B9: ='RAT '!B9 | F9: ='RAT '!F9
A10: Informações de Contato | F10: Matrícula / Nome - Funcionário Solicitante
A11: ='RAT '!A11 -> Responsável | F11: ='RAT '!F11 -> F2190439 - SISTEMA
A12: MÓDULO DEMANDANTE / BENEFICIÁRIO / CONTRATANTE PREENCHIMENTO PELO PREPOSTO DO BANCO DO BRASIL
A13: Matrícula | C13: Nome Funcionário Preposto
A15: Questionário | I15: Atendeu | K15: Não Atendeu
A16: Prazo de Atendimento
A17: Qualidade dos serviços executados
A18: Discrição e Presteza dos funcionários
A19: RESUMO DO ORÇAMENTO DOS SERVIÇOS EXECUTADOS
A20: Data / Hora Conclusão | F20: Valor de Materiais + Mão de Obra | I20: Valor Total
A21: ='RAT '!E75 -> 0 | F21: ='RAT '!F60 -> #VALUE! | G21: + | H21: ='RAT '!H60 -> #VALUE! | I21: ='RAT '!I60 -> #VALUE!
A22: Observações
A24: Sr. ADMINISTRADOR PREDIAL, antes de assinar o RAT (Relatório de Atendimento), deve-se observar que:
A25: 1. A Situação (código, em "Serviços Solicitados") foi preenchida adequadamente para cada serviço solicitado e que os serviços
A26: registrados como concluídos, ficaram sem pendências;
A27: 2. Os serviços solicitados, porém não executados ou executados parcialmente, tiveram um valor descontado no campo "Resumo do Orçamento dos
A28: Serviços Executados".
A29: 3. O documento deverá ser totalmente preenchido, em todos os campos e sem rasuras. Inutilizar os espaços em branco;
A30: 4. A segunda via do RAT deverá ficar arquivada na dependência beneficiária para consultas futuras;
A31: 5. Deve-se registrar no Portal de Manutenção da DISEC as informações contidas no RAT.
A32: Dúvidas quanto aos itens, quantitativos e valores aplicados aos serviços, deverão ser sanadas com a CONTRATADA durante o atendimento. Caso não
A33: ocorra o esclarecimento, consultar o CESUP SUPRIMENTOS.
A34: Lembramos que o ADMINISTRADOR PREDIAL é o responsável pela fiscalização dos serviços executados na dependência e que a
... A36: dos serviços
B38: ________________________________________________ | H38: ___________________________________________________________________________________
B39: VISTO REPRESENTANTE DA EMPRESA CONTRATADA | H39: CARIMBO E VISTO DA DEPENDÊNCIA
A41: Parecer do Responsável Técnico / Contratada | I41: ENGENHEIRO
I47: CARIMBO - NÚMERO / VISTO DO CREA
A48: O RAT deverá ser emitido em 3 vias, sendo: a 1° Depêndencia Beneficiária, 2° Empresa Contratada, e em 3° CESUP Suprimentos

Sheet Valores Unitários
B1: A interessada deverá prrencher os campos em amarelo abaixo.
C3: CONSERVAÇÃO PREDIAL
B4: PROPONENTE : | G4: LOTE: | H4: 07
B5: MAFFENG ENGENHARIA E MANUTENÇÃO LTDA | D5: CNPJ: | E5: 33.624.704/0001-94 | I5: DESCONTO: | J5: 0.1589
A7: Nº ITEM | B7: DESCRIÇÃO ITEM | C7: QTDE | D7: UN. | E7: UNITÁRIO MATERIAL | F7: UNITÁRIO MÃO DE OBRA | G7: TOTAL UNITÁRIO DO ITEM | H7: TOTAL MATERIAL ROTEIRO | I7: TOTAL MÃO DE OBRA ROTEIRO | J7: TOTAL GERAL ROTEIRO | P7: UNITÁRIO MATERIAL | Q7: UNITÁRIO MÃO DE OBRA
A8: 1 | B8: PRELIMINARES | G8: =SUBTOTAL(109,G9:G15) -> 3887.78 | H8: =SUBTOTAL(109,H9:H15) -> 375777 | I8: =SUBTOTAL(109,I9:I15) -> 155002.43 | J8: =SUBTOTAL(109,J9:J15) -> 530779.43 | N8: Desconto | O8: 0.1589
A9: 1.1 | B9: Chamado | C9: 860 | D9: un | E9: =ROUND(P9,2) -> 0 | F9: =ROUND(Q9,2) -> 78.47 | G9: =SUM(E9:F9) -> 78.47 | H9: =C9*E9 -> 0 | I9: =C9*F9 -> 67484.2 | J9: =SUM(E9:F9)*C9 -> 67484.2 | O9: =1-0.1589 -> 0.8411 | P9: 0 | Q9: 78.466219
A10: 1.2 | B10: Deslocamento | C10: 120000 | D10: km | E10: =ROUND(P10,2) -> 2.12 | F10: =ROUND(Q10,2) -> 0.48 | G10: =SUM(E10:F10) -> 2.6 | H10: =C10*E10 -> 254400 | I10: =C10*F10 -> 57600 | J10: =SUM(E10:F10)*C10 -> 312000 | P10: 2.119572 | Q10: 0.479427
A11: 1.3 | B11: Revisão de instalações | C11: 80 | D11: un | E11: =ROUND(P11,2) -> 96.2 | F11: =ROUND(Q11,2) -> 361.77 | G11: =SUM(E11:F11) -> 457.97 | H11: =C11*E11 -> 7696 | I11: =C11*F11 -> 28941.6 | J11: =SUM(E11:F11)*C11 -> 36637.6 | P11: 96.196607 | Q11: 361.77393
A12: 1.4 | B12: Acompanhamento técnico em Segurança do Trabalho | C12: 1 | D12: un | E12: =ROUND(P12,2) -> 0 | F12: =ROUND(Q12,2) -> 196.33 | G12: =SUM(E12:F12) -> 196.33 | H12: =C12*E12 -> 0 | I12: =C12*F12 -> 196.33 | J12: =SUM(E12:F12)*C12 -> 196.33 | P12: 0 | Q12: 196.32956
A13: 1.5 | B13: Chamado Preventivo | C13: 50 | D13: un | E13: =ROUND(P13,2) -> 2271.61 | F13: =ROUND(Q13,2) -> 0 | G13: =SUM(E13:F13) -> 2271.61 | H13: =C13*E13 -> 113580.5 | I13: =C13*F13 -> 0 | J13: =SUM(E13:F13)*C13 -> 113580.5 | P13: 2271.6092 | Q13: 0
A14: 1.6 | B14: Deslocamento Fluvial | C14: 1 | D14: Km | E14: =ROUND(P14,2) -> 0.84 | F14: =ROUND(Q14,2) -> 1.05 | G14: =SUM(E14:F14) -> 1.89 | H14: =C14*E14 -> 0.84 | I14: =C14*F14 -> 1.05 | J14: =SUM(E14:F14)*C14 -> 1.89 | P14: 0.8411 | Q14: 1.051375
A15: 1.7 | B15: Laudo técnico fotográfico - Elementos de Sinalização - Padrão BB | C15: 1 | D15: UN | E15: =ROUND(P15,2) -> 99.66 | F15: =ROUND(Q15,2) -> 779.25 | G15: =SUM(E15:F15) -> 878.91 | H15: =C15*E15 -> 99.66 | I15: =C15*F15 -> 779.25 | J15: =SUM(E15:F15)*C15 -> 878.91 | P15: 99.661939 | Q15: 779.25392
A16: 2 | B16: IMPLANTAÇÃO / ADMINISTRAÇÃO | E16: =ROUND(P16,2) -> 0 | F16: =ROUND(Q16,2) -> 0 | G16: =SUBTOTAL(109,G17:G52) -> 2313.03 | H16: =SUBTOTAL(109,H17:H52) -> 81930.18 | I16: =SUBTOTAL(109,I17:I52) -> 68493.47 | J16: =SUBTOTAL(109,J17:J52) -> 150423.65
A17: 2.1 | B17: Demolição manual de concreto simples | C17: 42 | D17: m³ | E17: =ROUND(P17,2) -> 0 | F17: =ROUND(Q17,2) -> 269.82 | G17: =SUM(E17:F17) -> 269.82 | H17: =C17*E17 -> 0 | I17: =C17*F17 -> 11332.44 | J17: =SUM(E17:F17)*C17 -> 11332.44 | P17: 0 | Q17: 269.81647
A18: 2.2 | B18: Demolição manual de alvenaria de elevação ou elemento vazado, incluindo revestimento | C18: 1 | D18: m³ | E18: =ROUND(P18,2) -> 0 | F18: =ROUND(Q18,2) -> 62.27 | G18: =SUM(E18:F18) -> 62.27 | H18: =C18*E18 -> 0 | I18: =C18*F18 -> 62.27 | J18: =SUM(E18:F18)*C18 -> 62.27 | P18: 0 | Q18: 62.266633
A19: 2.3 | B19: Demolição manual de revestimento em massa de parede ou teto ou Dry-Wall | C19: 535 | D19: m³ | E19: =ROUND(P19,2) -> 0 | F19: =ROUND(Q19,2) -> 7.14 | G19: =SUM(E19:F19) -> 7.14 | H19: =C19*E19 -> 0 | I19: =C19*F19 -> 3819.9 | J19: =SUM(E19:F19)*C19 -> 3819.9 | P19: 0 | Q19: 7.140939
A20: 2.4 | B20: Demolição de pisos em geral (ladrilho hidráulico, camada de enchimento, cerâmica, porcelanato, mármore, granito, pedra e madeira) - Manual | C20: 1 | D20: m² | E20: =ROUND(P20,2) -> 0 | F20: =ROUND(Q20,2) -> 29.06 | G20: =SUM(E20:F20) -> 29.06 | H20: =C20*E20 -> 0 | I20: =C20*F20 -> 29.06 | J20: =SUM(E20:F20)*C20 -> 29.06 | P20: 0 | Q20: 29.060005
A21: 2.5 | B21: Demolição de pisos em geral (ladrilho hidráulico, camada de enchimento, cerâmica, porcelanato, mármore, granito, pedra e madeira) - Mecanizado | C21: 207 | D21: m² | E21: =ROUND(P21,2) -> 23.95 | F21: =ROUND(Q21,2) -> 14.53 | G21: =SUM(E21:F21) -> 38.48 | H21: =C21*E21 -> 4957.65 | I21: =C21*F21 -> 3007.71 | J21: =SUM(E21:F21)*C21 -> 7965.36 | P21: 23.946117 | Q21: 14.525797
A22: 2.6 | B22: Demolição de pavimentação com pré-moldado de concreto ou intertravado | C22: 1 | D22: m² | E22: =ROUND(P22,2) -> 0 | F22: =ROUND(Q22,2) -> 14.53 | G22: =SUM(E22:F22) -> 14.53 | H22: =C22*E22 -> 0 | I22: =C22*F22 -> 14.53 | J22: =SUM(E22:F22)*C22 -> 14.53 | P22: 0 | Q22: 14.525797
A23: 2.7 | B23: Demolição de piso cimentado sobre lastro de concreto | C23: 1 | D23: m² | E23: =ROUND(P23,2) -> 0 | F23: =ROUND(Q23,2) -> 26.98 | G23: =SUM(E23:F23) -> 26.98 | H23: =C23*E23 -> 0 | I23: =C23*F23 -> 26.98 | J23: =SUM(E23:F23)*C23 -> 26.98 | P23: 0 | Q23: 26.982488
A24: 2.8 | B24: Demolição manual de forro, inclusive sistema de fixação/tarugamento | C24: 108 | D24: m² | E24: =ROUND(P24,2) -> 0 | F24: =ROUND(Q24,2) -> 8.3 | G24: =SUM(E24:F24) -> 8.3 | H24: =C24*E24 -> 0 | I24: =C24*F24 -> 896.4 | J24: =SUM(E24:F24)*C24 -> 896.4 | P24: 0 | Q24: 8.301657
A25: 2.9 | B25: Demolição de contrapiso/argamassa regularizante, isolante ou protetora | C25: 1 | D25: m² | E25: =ROUND(P25,2) -> 0 | F25: =ROUND(Q25,2) -> 10.38 | G25: =SUM(E25:F25) -> 10.38 | H25: =C25*E25 -> 0 | I25: =C25*F25 -> 10.38 | J25: =SUM(E25:F25)*C25 -> 10.38 | P25: 0 | Q25: 10.379174
A26: 2.10 | B26: Demolição de estrutura em madeira para telhado | C26: 1 | D26: m² | E26: =ROUND(P26,2) -> 0 | F26: =ROUND(Q26,2) -> 28.13 | G26: =SUM(E26:F26) -> 28.13 | H26: =C26*E26 -> 0 | I26: =C26*F26 -> 28.13 | J26: =SUM(E26:F26)*C26 -> 28.13 | P26: 0 | Q26: 28.126384
A27: 2.11 | B27: Retirada de cumeeira, espigão, rufo, calha ou chapim, perfil qualquer | C27: 41 | D27: m | E27: =ROUND(P27,2) -> 0 | F27: =ROUND(Q27,2) -> 13.6 | G27: =SUM(E27:F27) -> 13.6 | H27: =C27*E27 -> 0 | I27: =C27*F27 -> 557.6 | J27: =SUM(E27:F27)*C27 -> 557.6 | P27: 0 | Q27: 13.600587
A28: 2.12 | B28: Retirada de piso tátil com limpeza | C28: 133 | D28: m² | E28: =ROUND(P28,2) -> 14.28 | F28: =ROUND(Q28,2) -> 22.53 | G28: =SUM(E28:F28) -> 36.81 | H28: =C28*E28 -> 1899.24 | I28: =C28*F28 -> 2996.49 | J28: =SUM(E28:F28)*C28 -> 4895.73 | P28: 14.281878 | Q28: 22.533069
... A52: 2.36 | B52: Tela para Andaime | C52: 1 | D52: m² | E52: =ROUND(P52,2) -> 3.9 | F52: =ROUND(Q52,2) -> 3.01 | G52: =SUM(E52:F52) -> 6.91 | H52: =C52*E52 -> 3.9 | I52: =C52*F52 -> 3.01 | J52: =SUM(E52:F52)*C52 -> 6.91 | P52: 3.902704 | Q52: 3.011138
A53: 3 | B53: MOVIMENTO DE TERRA | E53: =ROUND(P53,2) -> 0 | F53: =ROUND(Q53,2) -> 0 | G53: 0 | H53: 0 | I53: 0 | J53: 0
A54: 4 | B54: FUNDAÇÃO | E54: =ROUND(P54,2) -> 0 | F54: =ROUND(Q54,2) -> 0 | G54: 0 | H54: 0 | I54: 0 | J54: 0
A55: 5 | B55: ESTRUTURA | E55: =ROUND(P55,2) -> 0 | F55: =ROUND(Q55,2) -> 0 | G55: =SUBTOTAL(109,G56:G59) -> 1556.33 | H55: =SUBTOTAL(109,H56:H59) -> 1378.65 | I55: =SUBTOTAL(109,I56:I59) -> 177.68 | J55: =SUBTOTAL(109,J56:J59) -> 1556.33
A56: 5.1 | B56: Base de concreto para fixação de TAA/TTE | C56: 1 | D56: m³ | E56: =ROUND(P56,2) -> 1011.06 | F56: =ROUND(Q56,2) -> 51.57 | G56: =SUM(E56:F56) -> 1062.63 | H56: =C56*E56 -> 1011.06 | I56: =C56*F56 -> 51.57 | J56: =SUM(E56:F56)*C56 -> 1062.63 | P56: 1011.0611 | Q56: 51.567841
A57: 5.2 | B57: Montagem e Desmontagem de escoramento em madeira. | C57: 1 | D57: m² | E57: =ROUND(P57,2) -> 157.71 | F57: =ROUND(Q57,2) -> 53.43 | G57: =SUM(E57:F57) -> 211.14 | H57: =C57*E57 -> 157.71 | I57: =C57*F57 -> 53.43 | J57: =SUM(E57:F57)*C57 -> 211.14 | P57: 157.71466 | Q57: 53.426672
A58: 5.3 | B58: Montagem e Desmontagem de escoramento metálico. | C58: 1 | D58: m² | E58: =ROUND(P58,2) -> 123.98 | F58: =ROUND(Q58,2) -> 46.19 | G58: =SUM(E58:F58) -> 170.17 | H58: =C58*E58 -> 123.98 | I58: =C58*F58 -> 46.19 | J58: =SUM(E58:F58)*C58 -> 170.17 | P58: 123.97814 | Q58: 46.193212
A59: 5.4 | B59: Concreto fck = 15 MPa, controle tipo "B", e = 10 cm, e armado com tela de aço CA-60 | C59: 1 | D59: m² | E59: =ROUND(P59,2) -> 85.9 | F59: =ROUND(Q59,2) -> 26.49 | G59: =SUM(E59:F59) -> 112.39 | H59: =C59*E59 -> 85.9 | I59: =C59*F59 -> 26.49 | J59: =SUM(E59:F59)*C59 -> 112.39 | P59: 85.901543 | Q59: 26.49465
A60: 6 | B60: ALVENARIAS E OUTRAS VEDAÇÕES | E60: =ROUND(P60,2) -> 0 | F60: =ROUND(Q60,2) -> 0 | G60: =SUBTOTAL(109,G61:G63) -> 311.58 | H60: =SUBTOTAL(109,H61:H63) -> 9523.53 | I60: =SUBTOTAL(109,I61:I63) -> 3803.2 | J60: =SUBTOTAL(109,J61:J63) -> 13326.73
A61: 6.1 | B61: Alvenaria com tijolo cerâmico furado | C61: 69 | D61: m² | E61: =ROUND(P61,2) -> 33.27 | F61: =ROUND(Q61,2) -> 38.28 | G61: =SUM(E61:F61) -> 71.55 | H61: =C61*E61 -> 2295.63 | I61: =C61*F61 -> 2641.32 | J61: =SUM(E61:F61)*C61 -> 4936.95 | P61: 33.273916 | Q61: 38.278461
A62: 6.2 | B62: Parede de gesso em placas duplas acartonado dry wall - inclusive para ambientes úmidos - RU | C62: 38 | D62: m² | E62: =ROUND(P62,2) -> 174.33 | F62: =ROUND(Q62,2) -> 13.46 | G62: =SUM(E62:F62) -> 187.79 | H62: =C62*E62 -> 6624.54 | I62: =C62*F62 -> 511.48 | J62: =SUM(E62:F62)*C62 -> 7136.02 | P62: 174.3348 | Q62: 13.4576
A63: 6.3 | B63: Rasgo e fechamento em alvenaria e piso | C63: 24 | D63: m | E63: =ROUND(P63,2) -> 25.14 | F63: =ROUND(Q63,2) -> 27.1 | G63: =SUM(E63:F63) -> 52.24 | H63: =C63*E63 -> 603.36 | I63: =C63*F63 -> 650.4 | J63: =SUM(E63:F63)*C63 -> 1253.76 | P63: 25.140479 | Q63: 27.100242
A64: 7 | B64: COBERTURA | E64: =ROUND(P64,2) -> 0 | F64: =ROUND(Q64,2) -> 0 | G64: =SUBTOTAL(109,G65:G79) -> 1457.33 | H64: =SUBTOTAL(109,H65:H79) -> 96390.6 | I64: =SUBTOTAL(109,I65:I79) -> 15889.46 | J64: =SUBTOTAL(109,J65:J79) -> 112280.06
A65: 7.1 | B65: Cobertura com telha de alumínio envernizada ou pintada, e=0,5 mm | C65: 17 | D65: m² | E65: =ROUND(P65,2) -> 89.24 | F65: =ROUND(Q65,2) -> 12.72 | G65: =SUM(E65:F65) -> 101.96 | H65: =C65*E65 -> 1517.08 | I65: =C65*F65 -> 216.24 | J65: =SUM(E65:F65)*C65 -> 1733.32 | P65: 89.24071 | Q65: 12.717432
...

Sheet Prefixos
A1: LOTE 07: MATO GROSSO DO SUL – Campo Grande e Aquidauana
A2: Relação das Dependências do Rot - Campo Grande (MS)
A5: PREFIXO | B5: DEPENDÊNCIAS | C5: MUNICÍPIO | D5: DISTÂNCIA EM RELAÇÃO A CIDADE BASE - IDA E VOLTA (KM) | E5: ENDEREÇO
A6: 48 | B6: AFONSO PENA | C6: CAMPO GRANDE | D6: 20 | E6: AV.AFONSO PENA,2202
A7: 552 | B7: COXIM | C7: COXIM | D7: 504 | E7: R.ANTONIO DE ALBUQUERQUE,248
A8: 753 | B8: RIO VERDE M.GROSSO | C8: RIO VERDE DE MATO GROSSO | D8: 402 | E8: R.BARAO DO RIO BRANCO,173
A9: 1147 | B9: SIDROLANDIA | C9: SIDROLANDIA | D9: 142 | E9: R.RIO GRANDE DO NORTE,160
A10: 1872 | B10: COSTA RICA | C10: COSTA RICA | D10: 652 | E10: AV.JOSE FERREIRA DA COSTA,1480
A11: 1873 | B11: CIDADE MORENA | C11: CAMPO GRANDE | D11: 20 | E11: R.JOAO PEDRO DE SOUZA,1275
A12: 1881 | B12: ESTILO CAMPO GRANDE | C12: CAMPO GRANDE | D12: 20 | E12: AV.DR.PAULO COELHO MACHADO,164
A13: 1997 | B13: ESTILO PANTANAL | C13: CAMPO GRANDE | D13: 20 | E13: AV.AFONSO PENA,2202
A14: 2431 | B14: PEDRO GOMES | C14: PEDRO GOMES | D14: 608 | E14: R.BAHIA,545
A15: 2576 | B15: S.PUBLICO C.GRANDE | C15: CAMPO GRANDE | D15: 20 | E15: AV.WALDIR DOS SANTOS PEREIRA,S/N
A16: 2609 | B16: CORP BANK MS | C16: CAMPO GRANDE | D16: 20 | E16: R.QUINZE DE NOVEMBRO,2550
A17: 2620 | B17: SAO GABRIEL DO OESTE | C17: SAO GABRIEL DO OESTE | D17: 272 | E17: R.MINAS GERAIS,1305
... A38: 3929 | B38: BANDEIRANTES | C38: BANDEIRANTES | D38: 137 | E38: R.DRA.JACIRA ONORIO LYRIO,1340 - - - - CEP: 0
A57: Relação das Dependências do Rot - Aquidauana (MS)
A60: PREFIXO | B60: DEPENDÊNCIAS | C60: MUNICÍPIO | D60: DISTÂNCIA EM RELAÇÃO A CIDADE BASE - IDA E VOLTA (KM) | E60: ENDEREÇO
A61: 14 | B61: CORUMBA | C61: CORUMBA | D61: 594 | E61: R.TREZE DE JUNHO,914
A62: 123 | B62: AQUIDAUANA | C62: AQUIDAUANA | D62: 10 | E62: R.MANOEL A.PAES DE BARROS,535
A63: 543 | B63: GUIA LOPES DA LAGUNA | C63: GUIA LOPES DA LAGUNA | D63: 278 | E63: AV.VISC.DE TAUNAY,608
A64: 623 | B64: MIRANDA | C64: MIRANDA | D64: 154 | E64: R.TIRADENTES,364
A65: 742 | B65: PORTO MURTINHO | C65: PORTO MURTINHO | D65: 694 | E65: PCA.THOMAZ LARANJEIRAS,34
A66: 1031 | B66: BONITO-MS | C66: BONITO | D66: 258 | E66: R.LUIZ DA COSTA LEITE,2279
A67: 2340 | B67: NIOAQUE | C67: NIOAQUE | D67: 186 | E67: R.BENJAMIN CONSTANT,342
A68: 3093 | B68: DOIS IRMAOS BURITI | C68: DOIS IRMAOS DO BURITI | D68: 144 | E68: AV.REGINALDO LEMES DA SILVA,564
A69: 3930 | B69: BODOQUENA | C69: BODOQUENA | D69: 268 | E69: R.TREZE DE MAIO,305
